Workbook

Sheet DIA_Danh Mục Đầu Tư
A1: DIA+ - DANH MỤC ĐẦU TƯ
A3: STT | B3: Danh mục | C3: Số lượng | D3: Đơn giá | E3: Thành tiền | F3: Thời gian sử dụng | G3: Khấu hao / phân bổ | H3: Ghi chú
A4: 1 | B4: Laptop Lenovo LOQ | C4: ='DIA_Giả Định'!$N$129 -> 5 | D4: ='DIA_Giả Định'!$N$130 -> 24700000 | E4: =C4*D4 -> 123500000 | F4: ='DIA_Giả Định'!$N$65 -> 4 | G4: Có | H4: Mua 5 Laptop cho công ty (Chi 1 lần)
A5: 2 | B5: Điện thoại Iphone/demo test | C5: ='DIA_Giả Định'!$N$131 -> 1 | D5: ='DIA_Giả Định'!$N$132 -> 16300000 | E5: =C5*D5 -> 16300000 | F5: ='DIA_Giả Định'!$N$65 -> 4 | G5: Có | H5: Giá ngày 20/07/2026 tham khảo tại CellphoneS
A6: 3 | B6: Lương đội ngũ công nghệ | C6: 1 | D6: ='DIA_Giả Định'!$N$75*12 -> 300000000 | E6: ='DIA_Giả Định'!$N$75*12 -> 300000000 | F6: 1 | H6: 30.000.000đ/tháng
A7: 4 | B7: Thuê mặt bằng văn phòng co - working | C7: 1 | D7: 0 | E7: 0 | F7: 0 | H7: Năm đầu chưa thuê mặt bằng
A8: 5 | B8: Bảo mật và lưu trữ thông tin | C8: =SUM(C9:C13) -> 5 | D8: =SUM(D9:D13) -> 96000000 | E8: =SUM(E9:E13) -> 96000000 | F8: 1 | G8: Có
B9: - Bảo mật Đám mây (Cloudflare Pro/WAF) | C9: ='DIA_Giả Định'!$N$133 -> 1 | D9: ='DIA_Giả Định'!$N$134 -> 6400000 | E9: =C9*D9 -> 6400000 | F9: 1,0 năm | G9: Có | H9: Giá được tham khảo tại trang web cloudflare.com với gói Pro $240/năm tương đương $20/tháng và tỷ giá được xác định theo ngày 20/07/2026 với 1 USD = 26.940 VND | J9: Note: - Do thuê mặt bằng là Co - working nó sẽ bao hàm hết, không cần trả phí điện nước hay mạng.
B10: - Vercel Pro | C10: 1 | D10: 6500000 | E10: =C10*D10 -> 6500000 | F10: 1,0 năm | G10: Có | H10: Hosting cho Frontend (React/PWA)
B11: - Render / AWS EC2 | C11: 1 | D11: 2000000 | E11: =C11*D11 -> 2000000 | F11: 1,0 năm | G11: Có | H11: Hosting cho Backend (Node.js)
B12: - Supabase (Pro) | C12: 1 | D12: 8100000 | E12: =C12*D12 -> 8100000 | F12: 1,0 năm | G12: Có | H12: Database PostgreSQL lưu bệnh án bảo mật
B13: - AWS S3 | C13: 1 | D13: 73000000 | E13: =C13*D13 -> 73000000 | F13: 1,0 năm | G13: Có | H13: lưu trữ ảnh đơn thuốc
A14: 6 | B14: Bản quyền Microsoft 365 Family chính hãng (có AI Copilot) | C14: ='DIA_Giả Định'!$N$135 -> 1 | D14: ='DIA_Giả Định'!$N$136 -> 2600000 | E14: =C14*D14 -> 2600000 | F14: ='DIA_Giả Định'!$N$64 -> 1 | G14: Có
A15: 7 | B15: Tích hợp AI | C15: ='DIA_Giả Định'!$N$139 -> 2 | D15: =SUM(D16+D17) -> 11300000 | E15: =SUM(E16+E17) -> 11300000 | F15: ='DIA_Giả Định'!$N$64 -> 1 | G15: Có
B16: - AI của Google Pro (đã bao gồm VAT) | C16: 1 | D16: 4100000 | E16: =C16*D16 -> 4100000 | F16: 1,0 năm | G16: Có | H16: Giá được giảm khi sử dụng năm đầu, giá sau đó là 5.555.55 6 ₫/năm
B17: - Claude Team (Standard seat) (đã bao gồm VAT) | C17: 1 | D17: 7200000 | E17: =C17*D17 -> 7200000 | F17: 1,0 năm | G17: Có | H17: Giá được tham khảo tại trang webclaude.com với gói Team $240/năm tương đương $20/tháng và tỷ giá được xác định theo ngày 20/07/2026 với 1 USD = 26.940 VND
A18: 8 | B18: Tư vấn pháp lý và đăng ký kinh doanh | C18: ='DIA_Giả Định'!$N$141 -> 6 | D18: =SUM(D19:D24) -> 41000000 | E18: =SUM(E19:E24) -> 41000000 | F18: 0 | G18: Không
B19: - Thuê đơn vị hỗ trợ đăng ký thành lập doanh nghiệp đầy đủ (đã bao gồm ký quỹ ngân hàng) | C19: 1 | D19: 6000000 | E19: 6000000 | F19: 0,0 năm | G19: Không | H19: Đã bao trọn gói, ký quỹ và thuê địa chỉ
B20: - Kế toán dịch vụ (phí 1 tháng) | C20: 1 | D20: 5000000 | E20: 5000000 | F20: 0,0 năm | G20: Không | H20: Báo cáo hàng tháng
B21: - Đăng ký sở hữu trí tuệ (nhãn hiệu) | C21: 1 | D21: ='DIA_Giả Định'!$N$103 -> 5000000 | E21: ='DIA_Giả Định'!$N$103 -> 5000000 | F21: 0,0 năm | G21: Không | H21: Đã bao gồm phí đăng ký và thuê Đại lý sở hữu công nghiệp
B22: - Tư vấn pháp lý y tế | C22: 1 | D22: 20000000 | E22: 20000000 | F22: 0,0 năm | G22: Không | H22: Chính sách dữ liệu y tế (HIPAA/VN)
B23: - Đăng ký bản quyền phần mềm app | C23: 1 | D23: 3000000 | E23: 3000000 | F23: 0,0 năm | G23: Không | H23: Thuê dịch vụ, giá tham khảo tại Luật Trí Nam
B24: - Giấy phép Thương mại điện tử (Bộ Công Thương) | C24: 1 | D24: 2000000 | E24: 2000000 | F24: 0,0 năm | G24: Không | H24: Thuê dịch vụ soạn hồ sơ
A25: 9 | B25: Hạ tầng công nghệ | C25: =SUM(C26:C33) -> 12 | D25: =SUM(D26:D33) -> 259850000 | E25: =SUM(E26:E33) -> 264650000 | F25: 1 | G25: có
B26: - SendGrid / Resend Gói Essentials (50K email/tháng) | C26: 1 | D26: 6500000 | E26: 6500000 | F26: 1 | G26: có | H26: Hệ thống gửi Email OTP tự động
B27: - Zalo ZNS / SMS | C27: 1 | D27: 151200000 | E27: 151200000 | F27: 1 | G27: có | H27: 1. Phí đăng ký thương hiệu chính thống bảo mật y tế: ~ 600.000đ/năm 2. Ước tính giá tin nhắn 1 năm: 50.000 tin / tháng ~150.600.000đ/năm
B28: - Apple Developer | C28: 1 | D28: 2700000 | E28: 2700000 | F28: 1 | G28: có | H28: Tài khoản App Store (Thanh toán năm)
B29: - Google Play Console | C29: 1 | D29: 700000 | E29: 700000 | F29: 1 | G29: có | H29: Tài khoản CH Play (Đóng 1 lần vĩnh viễn)
B30: - Tên miền (domain) | C30: 1 | D30: 700000 | E30: 700000 | F30: 1 | G30: có | H30: diaplus.vn / diaplus.app
B31: - Email workspace | C31: 1 | D31: 850000 | E31: 850000 | F31: 1 | G31: có | H31: Email doanh nghiệp (vd: contact@diaplus.vn)
B32: - GitHub Team/Pro | C32: 5 | D32: 1200000 | E32: =C32*D32 -> 6000000 | F32: 1 | G32: có | H32: Quản lý mã nguồn nhóm
B33: - Thiết kế UI/UX - Loveable | C33: ='DIA_Giả Định'!$N$92 -> 1 | D33: ='DIA_Giả Định'!$N$93 -> 96000000 | E33: =C33*D33 -> 96000000 | F33: 1 | G33: có | H33: Thiết kế UI/UX
A34: 10 | B34: Dự phòng ban đầu - dự trù chi phí phát sinh | C34: ='DIA_Giả Định'!$N$137 -> 2 | D34: ='DIA_Giả Định'!$N$138 -> 320000000 | E34: ='DIA_Giả Định'!$N$138 -> 320000000 | F34: ='DIA_Giả Định'!$N$64 -> 1 | G34: kHÔNG
B35: - Phát triển MVP | C35: 1 | D35: 220000000 | E35: 220000000 | F35: ='DIA_Giả Định'!$N$64 -> 1 | G35: kHÔNG | H35: Sản phẩm khả dụng tối thiểu)
B36: - Backend và cơ sở dữ liệu | C36: 1 | D36: 180000000 | E36: 180000000 | F36: ='DIA_Giả Định'!$N$64 -> 1 | G36: kHÔNG | H36: Bảo vệ thông tin bệnh nhân và Tối ưu chi phí & Hiệu năng
A37: TỔNG DANH MỤC ĐẦU TƯ CHI TIẾT | E37: =SUM(E4:E8,E14:E15,E18,E25,E34) -> 1175350000
H40: .

Sheet DIA_Giả Định
A1: DIA+ - GIẢ ĐỊNH ĐẦU VÀO & KỊCH BẢN 3 NĂM
B2: Cơ sở | D2: Note: - Thận trọng: Nếu mọi thứ diễn ra không thuận lợi lắm. - Cơ sở: Kịch bản có khả năng xảy ra nhất - Tích cực: Nếu mọi thứ diễn ra thuận lợi hơn dự kiến
A3: Nhóm | B3: Mã biến | C3: Biến số | D3: Đơn vị | E3: Thận trọng Năm 1 | F3: Thận trọng Năm 2 | G3: Thận trọng Năm 3 | H3: Cơ sở Năm 1 | I3: Cơ sở Năm 2 | J3: Cơ sở Năm 3 | K3: Tích cực Năm 1 | L3: Tích cực Năm 2 | M3: Tích cực Năm 3 | N3: Kịch bản chọn Năm 1 | O3: Kịch bản chọn Năm 2 | P3: Kịch bản chọn Năm 3 | Q3: Nguồn / căn cứ | R3: Trạng thái
A4: A. NGƯỜI DÙNG
A5: Người dùng | B5: months_year | C5: Số tháng trong năm | D5: tháng | E5: 12 | F5: 12 | G5: 12 | H5: 12 | I5: 12 | J5: 12 | K5: 12 | L5: 12 | M5: 12 | N5: =IF($B$2="Thận trọng",E5,IF($B$2="Cơ sở",H5,K5)) -> 12 | O5: =IF($B$2="Thận trọng",F5,IF($B$2="Cơ sở",I5,L5)) -> 12 | P5: =IF($B$2="Thận trọng",G5,IF($B$2="Cơ sở",J5,M5)) -> 12 | Q5: Quy ước mô hình | R5: Quy ước
A6: Người dùng | B6: users_total | C6: Tổng người dùng đăng ký | D6: người | E6: 20000 | F6: 30000 | G6: 45000 | H6: 40000 | I6: 50000 | J6: 70000 | K6: 50000 | L6: 70000 | M6: 100000 | N6: =IF($B$2="Thận trọng",E6,IF($B$2="Cơ sở",H6,K6)) -> 40000 | O6: =IF($B$2="Thận trọng",F6,IF($B$2="Cơ sở",I6,L6)) -> 50000 | P6: =IF($B$2="Thận trọng",G6,IF($B$2="Cơ sở",J6,M6)) -> 70000 | Q6: Giả định với mục tiêu tăng trưởng theo 3 giai đoạn: thử nghiệm – tăng trưởng – mở rộng. | R6: Đã xác nhận
A7: Người dùng | B7: mau_rate | C7: Tỷ lệ người dùng hoạt động MAU | D7: % | E7: 0.3 | F7: 0.4 | G7: 0.5 | H7: 0.35 | I7: 0.45 | J7: 0.55 | K7: 0.4 | L7: 0.5 | M7: 0.6 | N7: =IF($B$2="Thận trọng",E7,IF($B$2="Cơ sở",H7,K7)) -> 0.35 | O7: =IF($B$2="Thận trọng",F7,IF($B$2="Cơ sở",I7,L7)) -> 0.45 | P7: =IF($B$2="Thận trọng",G7,IF($B$2="Cơ sở",J7,M7)) -> 0.55 | Q7: Giả định ban đầu | R7: Đã xác nhận
A8: Người dùng | B8: pro_conv | C8: Tỷ lệ chuyển đổi Free → Pro | D8: % | E8: 0.03 | F8: 0.04 | G8: 0.05 | H8: 0.04 | I8: 0.05 | J8: 0.06 | K8: 0.05 | L8: 0.06 | M8: 0.07 | N8: =IF($B$2="Thận trọng",E8,IF($B$2="Cơ sở",H8,K8)) -> 0.04 | O8: =IF($B$2="Thận trọng",F8,IF($B$2="Cơ sở",I8,L8)) -> 0.05 | P8: =IF($B$2="Thận trọng",G8,IF($B$2="Cơ sở",J8,M8)) -> 0.06 | Q8: Giả định | R8: Đã xác nhận
A9: Người dùng | B9: pro_monthly_share | C9: Tỷ lệ Pro trả theo tháng | D9: % | E9: 0.75 | F9: 0.7 | G9: 0.65 | H9: 0.7 | I9: 0.65 | J9: 0.6 | K9: 0.65 | L9: 0.6 | M9: 0.55 | N9: =IF($B$2="Thận trọng",E9,IF($B$2="Cơ sở",H9,K9)) -> 0.7 | O9: =IF($B$2="Thận trọng",F9,IF($B$2="Cơ sở",I9,L9)) -> 0.65 | P9: =IF($B$2="Thận trọng",G9,IF($B$2="Cơ sở",J9,M9)) -> 0.6 | Q9: Giả định ban đầu | R9: Đã xác nhận
A10: Người dùng | B10: pro_annual_share | C10: Tỷ lệ Pro trả theo năm | D10: % | E10: 0.25 | F10: 0.3 | G10: 0.35 | H10: 0.3 | I10: 0.35 | J10: 0.4 | K10: 0.35 | L10: 0.4 | M10: 0.45 | N10: =IF($B$2="Thận trọng",E10,IF($B$2="Cơ sở",H10,K10)) -> 0.3 | O10: =IF($B$2="Thận trọng",F10,IF($B$2="Cơ sở",I10,L10)) -> 0.35 | P10: =IF($B$2="Thận trọng",G10,IF($B$2="Cơ sở",J10,M10)) -> 0.4 | Q10: Giả định ban đầu | R10: Đã xác nhận
A11: Người dùng | B11: clinic_monthly_share | C11: Tỷ lệ Clinic trả theo tháng | D11: % | E11: 0.8 | F11: 0.7 | G11: 0.6 | H11: 0.6 | I11: 0.45 | J11: 0.35 | K11: 0.4 | L11: 0.25 | M11: 0.15 | N11: =IF($B$2="Thận trọng",E11,IF($B$2="Cơ sở",H11,K11)) -> 0.6 | O11: =IF($B$2="Thận trọng",F11,IF($B$2="Cơ sở",I11,L11)) -> 0.45 | P11: =IF($B$2="Thận trọng",G11,IF($B$2="Cơ sở",J11,M11)) -> 0.35 | Q11: Giả định ban đầu | R11: Đã xác nhận
A12: Người dùng | B12: clinic_annual_share | C12: Tỷ lệ Clinc trả theo năm | D12: % | E12: 0.2 | F12: 0.3 | G12: 0.4 | H12: 0.4 | I12: 0.55 | J12: 0.65 | K12: 0.6 | L12: 0.75 | M12: 0.85 | N12: =IF($B$2="Thận trọng",E12,IF($B$2="Cơ sở",H12,K12)) -> 0.4 | O12: =IF($B$2="Thận trọng",F12,IF($B$2="Cơ sở",I12,L12)) -> 0.55 | P12: =IF($B$2="Thận trọng",G12,IF($B$2="Cơ sở",J12,M12)) -> 0.65 | Q12: Giả định ban đầu | R12: Đã xác nhận
A13: Người dùng | B13: mau | C13: Số người thật sự dùng (MAU) | D13: người | E13: =E6*E7 -> 6000 | F13: =F6*F7 -> 12000 | G13: =G6*G7 -> 22500 | H13: =H6*H7 -> 14000 | I13: =I6*I7 -> 22500 | J13: =J6*J7 -> 38500 | K13: =K6*K7 -> 20000 | L13: =L6*L7 -> 35000 | M13: =M6*M7 -> 60000 | N13: =IF($B$2="Thận trọng",E13,IF($B$2="Cơ sở",H13,K13)) -> 14000 | O13: =IF($B$2="Thận trọng",F13,IF($B$2="Cơ sở",I13,L13)) -> 22500 | P13: =IF($B$2="Thận trọng",G13,IF($B$2="Cơ sở",J13,M13)) -> 38500 | Q13: Giả định ban đầu | R13: Đã xác nhận
A14: Người dùng | B14: b2c_mau | C14: Số người thật sự dùng phân khúc bệnh nhân | D14: người | E14: 5950 | F14: 11900 | G14: 22300 | H14: 13900 | I14: 22350 | J14: 38250 | K14: 19850 | L14: 34800 | M14: 59650 | N14: =IF($B$2="Thận trọng",E14,IF($B$2="Cơ sở",H14,K14)) -> 13900 | O14: =IF($B$2="Thận trọng",F14,IF($B$2="Cơ sở",I14,L14)) -> 22350 | P14: =IF($B$2="Thận trọng",G14,IF($B$2="Cơ sở",J14,M14)) -> 38250 | Q14: Giả định ban đầu | R14: Đã xác nhận
A15: Người dùng | B15: b2c_clinic_mau | C15: Số người thật sự dùng phân khúc phòng khám | D15: người | E15: =E13-E14 -> 50 | F15: =F13-F14 -> 100 | G15: =G13-G14 -> 200 | H15: =H13-H14 -> 100 | I15: =I13-I14 -> 150 | J15: =J13-J14 -> 250 | K15: =K13-K14 -> 150 | L15: =L13-L14 -> 200 | M15: =M13-M14 -> 350 | N15: =IF($B$2="Thận trọng",E15,IF($B$2="Cơ sở",H15,K15)) -> 100 | O15: =IF($B$2="Thận trọng",F15,IF($B$2="Cơ sở",I15,L15)) -> 150 | P15: =IF($B$2="Thận trọng",G15,IF($B$2="Cơ sở",J15,M15)) -> 250 | Q15: Giả định ban đầu | R15: Đã xác nhận
A16: Người dùng | B16: b2c_retention_monthly | C16: Tỷ lệ giữ chân hằng tháng phân khúc bệnh nhân | D16: % | E16: 0.915 | F16: 0.92 | G16: 0.925 | H16: 0.935 | I16: 0.942 | J16: 0.95 | K16: 0.952 | L16: 0.958 | M16: 0.965 | N16: =IF($B$2="Thận trọng",E16,IF($B$2="Cơ sở",H16,K16)) -> 0.935 | O16: =IF($B$2="Thận trọng",F16,IF($B$2="Cơ sở",I16,L16)) -> 0.942 | P16: =IF($B$2="Thận trọng",G16,IF($B$2="Cơ sở",J16,M16)) -> 0.95 | Q16: Giả định ban đầu | R16: Đã xác nhận
A17: Người dùng | B17: b2c_churn_monthly | C17: Tỷ lệ rời bỏ hằng tháng phân khúc bệnh nhân | D17: % | E17: =100% - E16 -> 0.085 | F17: =100% - F16 -> 0.08 | G17: =100% - G16 -> 0.075 | H17: =100% - H16 -> 0.065 | I17: =100% - I16 -> 0.058 | J17: =100% - J16 -> 0.05 | K17: =100% - K16 -> 0.048 | L17: =100% - L16 -> 0.042 | M17: =100% - M16 -> 0.035 | N17: =IF($B$2="Thận trọng",E17,IF($B$2="Cơ sở",H17,K17)) -> 0.065 | O17: =IF($B$2="Thận trọng",F17,IF($B$2="Cơ sở",I17,L17)) -> 0.058 | P17: =IF($B$2="Thận trọng",G17,IF($B$2="Cơ sở",J17,M17)) -> 0.05 | Q17: Giả định ban đầu | R17: Đã xác nhận
A18: Người dùng | B18: b2b_retention_monthly | C18: Tỷ lệ giữ chân hằng tháng phân khúc phòng khám | D18: % | E18: 0.965 | F18: 0.97 | G18: 0.975 | H18: 0.982 | I18: 0.986 | J18: 0.99 | K18: 0.991 | L18: 0.993 | M18: 0.995 | N18: =IF($B$2="Thận trọng",E18,IF($B$2="Cơ sở",H18,K18)) -> 0.982 | O18: =IF($B$2="Thận trọng",F18,IF($B$2="Cơ sở",I18,L18)) -> 0.986 | P18: =IF($B$2="Thận trọng",G18,IF($B$2="Cơ sở",J18,M18)) -> 0.99 | Q18: Giả định ban đầu | R18: Đã xác nhận
A19: Người dùng | B19: b2b_churn_monthly | C19: Tỷ lệ rời bỏ hằng tháng phân khúc phòng khám | D19: % | E19: =100% - E18 -> 0.035 | F19: =100% - F18 -> 0.03 | G19: =100% - G18 -> 0.025 | H19: =100% - H18 -> 0.018 | I19: =100% - I18 -> 0.014 | J19: =100% - J18 -> 0.01 | K19: =100% - K18 -> 0.009 | L19: =100% - L18 -> 0.007 | M19: =100% - M18 -> 0.005 | N19: =IF($B$2="Thận trọng",E19,IF($B$2="Cơ sở",H19,K19)) -> 0.018 | O19: =IF($B$2="Thận trọng",F19,IF($B$2="Cơ sở",I19,L19)) -> 0.014 | P19: =IF($B$2="Thận trọng",G19,IF($B$2="Cơ sở",J19,M19)) -> 0.01 | Q19: Giả định ban đầu | R19: Đã xác nhận
A20: Người dùng | B20: new_users | C20: Tổng số người dùng mới trong năm | D20: người | E20: =E21+E22 -> 6000 | F20: =F21+F22 -> 6507.5 | G20: =G21+G22 -> 11455 | H20: =H21+H22 -> 14000 | I20: =I21+I22 -> 9405.3 | J20: =J21+J22 -> 17298.4 | K20: =K21+K22 -> 20000 | L20: =L21+L22 -> 15954.15 | M20: =M21+M22 -> 26463 | N20: =IF($B$2="Thận trọng",E20,IF($B$2="Cơ sở",H20,K20)) -> 14000 | O20: =IF($B$2="Thận trọng",F20,IF($B$2="Cơ sở",I20,L20)) -> 9405.3 | P20: =IF($B$2="Thận trọng",G20,IF($B$2="Cơ sở",J20,M20)) -> 17298.4 | Q20: Giả định, chênh lệch mục tiêu người dùng cuối năm | R20: Đã xác nhận
A21: Người dùng | B21: b2c_new_users_annual | C21: Tổng số người dùng mới là bệnh nhân trong năm | D21: người | E21: =E14 -> 5950 | F21: =F14-E14*E16 -> 6455.75 | G21: =G14-F14*F16 -> 11352 | H21: =H14 -> 13900 | I21: =I14-H14*H16 -> 9353.5 | J21: =J14-I14*I16 -> 17196.3 | K21: =K14 -> 19850 | L21: =L14-K14*K16 -> 15902.8 | M21: =M14-L14*L16 -> 26311.6 | N21: =IF($B$2="Thận trọng",E21,IF($B$2="Cơ sở",H21,K21)) -> 13900 | O21: =IF($B$2="Thận trọng",F21,IF($B$2="Cơ sở",I21,L21)) -> 9353.5 | P21: =IF($B$2="Thận trọng",G21,IF($B$2="Cơ sở",J21,M21)) -> 17196.3 | Q21: Giả định ban đầu | R21: Đã xác nhận
A22: Người dùng | B22: b2b_new_clinics_annual | C22: Tổng số người dùng mới là phòng khám trong năm | D22: người | E22: =E15 -> 50 | F22: =F15-E15*E18 -> 51.75 | G22: =G15-F15*F18 -> 103 | H22: =H15 -> 100 | I22: =I15-H15*H18 -> 51.8 | J22: =J15-I15*I18 -> 102.1 | K22: =K15 -> 150 | L22: =L15-K15*K18 -> 51.35 | M22: =M15-L15*L18 -> 151.4 | N22: =IF($B$2="Thận trọng",E22,IF($B$2="Cơ sở",H22,K22)) -> 100 | O22: =IF($B$2="Thận trọng",F22,IF($B$2="Cơ sở",I22,L22)) -> 51.8 | P22: =IF($B$2="Thận trọng",G22,IF($B$2="Cơ sở",J22,M22)) -> 102.1 | Q22: Giả định ban đầu | R22: Đã xác nhận
A23: Người dùng | B23: scans_per_mau | C23: Lượt quét đơn thuốc / MAU / tháng | D23: lượt | E23: 0.8 | F23: 1 | G23: 1.2 | H23: 1 | I23: 1.2 | J23: 1.5 | K23: 1.2 | L23: 1.5 | M23: 1.8 | N23: =IF($B$2="Thận trọng",E23,IF($B$2="Cơ sở",H23,K23)) -> 1 | O23: =IF($B$2="Thận trọng",F23,IF($B$2="Cơ sở",I23,L23)) -> 1.2 | P23: =IF($B$2="Thận trọng",G23,IF($B$2="Cơ sở",J23,M23)) -> 1.5 | Q23: Giả định theo mức sử dụng AI/OCR | R23: Đã xác nhận
A24: B. KHÁCH HÀNG TỔ CHỨC
A25: Tổ chức | B25: hospitals_end | C25: Số bệnh viện cuối năm | D25: cơ sở | E25: 1 | F25: 3 | G25: 6 | H25: 2 | I25: 5 | J25: 10 | K25: 3 | L25: 8 | M25: 15 | N25: =IF($B$2="Thận trọng",E25,IF($B$2="Cơ sở",H25,K25)) -> 2 | O25: =IF($B$2="Thận trọng",F25,IF($B$2="Cơ sở",I25,L25)) -> 5 | P25: =IF($B$2="Thận trọng",G25,IF($B$2="Cơ sở",J25,M25)) -> 10 | Q25: Năm 1 ưu tiên pilot; năm 2–3 mở rộng qua đối tác y tế. | R25: Đã xác nhận
A26: Tổ chức | B26: clinics_end | C26: Số phòng khám cuối năm | D26: cơ sở | E26: 3 | F26: 10 | G26: 15 | H26: 5 | I26: 15 | J26: 30 | K26: 8 | L26: 22 | M26: 40 | N26: =IF($B$2="Thận trọng",E26,IF($B$2="Cơ sở",H26,K26)) -> 5 | O26: =IF($B$2="Thận trọng",F26,IF($B$2="Cơ sở",I26,L26)) -> 15 | P26: =IF($B$2="Thận trọng",G26,IF($B$2="Cơ sở",J26,M26)) -> 30 | Q26: Giả định theo chiến lược B2B2C | R26: Đã xác nhận
A27: Tổ chức | B27: new_hospitals | C27: Bệnh viện ký mới trong năm | D27: cơ sở | E27: 1 | F27: 2 | G27: 3 | H27: 2 | I27: 3 | J27: 5 | K27: 3 | L27: 5 | M27: 7 | N27: =IF($B$2="Thận trọng",E27,IF($B$2="Cơ sở",H27,K27)) -> 2 | O27: =IF($B$2="Thận trọng",F27,IF($B$2="Cơ sở",I27,L27)) -> 3 | P27: =IF($B$2="Thận trọng",G27,IF($B$2="Cơ sở",J27,M27)) -> 5 | Q27: Giả định pipeline bán hàng | R27: Đã xác nhận
A28: Tổ chức | B28: new_clinics | C28: Phòng khám ký mới trong năm | D28: cơ sở | E28: 3 | F28: 7 | G28: 12 | H28: 5 | I28: 10 | J28: 20 | K28: 8 | L28: 14 | M28: 28 | N28: =IF($B$2="Thận trọng",E28,IF($B$2="Cơ sở",H28,K28)) -> 5 | O28: =IF($B$2="Thận trọng",F28,IF($B$2="Cơ sở",I28,L28)) -> 10 | P28: =IF($B$2="Thận trọng",G28,IF($B$2="Cơ sở",J28,M28)) -> 20 | Q28: Giả định pipeline bán hàng | R28: Đã xác nhận
A29: Tổ chức | B29: new_facilities | C29: Tổng cơ sở ký mới trong năm | D29: cơ sở | E29: =SUM(E27+E28) -> 4 | F29: =SUM(F27+F28) -> 9 | G29: =SUM(G27+G28) -> 15 | H29: =SUM(H27+H28) -> 7 | I29: =SUM(I27+I28) -> 13 | J29: =SUM(J27+J28) -> 25 | K29: =SUM(K27+K28) -> 11 | L29: =SUM(L27+L28) -> 19 | M29: =SUM(M27+M28) -> 35 | N29: =IF($B$2="Thận trọng",E29,IF($B$2="Cơ sở",H29,K29)) -> 7 | O29: =IF($B$2="Thận trọng",F29,IF($B$2="Cơ sở",I29,L29)) -> 13 | P29: =IF($B$2="Thận trọng",G29,IF($B$2="Cơ sở",J29,M29)) -> 25 | Q29: Tổng cơ sở ký mới | R29: Đã xác nhận
A30: Tổ chức | B30: avg_active_new_factor | C30: Tỷ lệ hoạt động bình quân của cơ sở ký mới | D30: % | E30: 0.5 | F30: 0.5 | G30: 0.5 | H30: 0.5 | I30: 0.5 | J30: 0.5 | K30: 0.5 | L30: 0.5 | M30: 0.5 | N30: =IF($B$2="Thận trọng",E30,IF($B$2="Cơ sở",H30,K30)) -> 0.5 | O30: =IF($B$2="Thận trọng",F30,IF($B$2="Cơ sở",I30,L30)) -> 0.5 | P30: =IF($B$2="Thận trọng",G30,IF($B$2="Cơ sở",J30,M30)) -> 0.5 | Q30: Giả định ký hợp đồng đều trong năm | R30: Đã xác nhận
A31: Tổ chức | B31: patients_hospital | C31: Bệnh nhân trung bình / bệnh viện | D31: người | E31: 3000 | F31: 4000 | G31: 5000 | H31: 4000 | I31: 5000 | J31: 6000 | K31: 5000 | L31: 6500 | M31: 8000 | N31: =IF($B$2="Thận trọng",E31,IF($B$2="Cơ sở",H31,K31)) -> 4000 | O31: =IF($B$2="Thận trọng",F31,IF($B$2="Cơ sở",I31,L31)) -> 5000 | P31: =IF($B$2="Thận trọng",G31,IF($B$2="Cơ sở",J31,M31)) -> 6000 | Q31: DIAPLUS.docx: 5.000–10.000 bệnh nhân/bệnh viện | R31: Tham chiếu DIA+
A32: Tổ chức | B32: patients_clinic | C32: Bệnh nhân trung bình / phòng khám | D32: người | E32: 300 | F32: 400 | G32: 500 | H32: 400 | I32: 600 | J32: 800 | K32: 500 | L32: 800 | M32: 1000 | N32: =IF($B$2="Thận trọng",E32,IF($B$2="Cơ sở",H32,K32)) -> 400 | O32: =IF($B$2="Thận trọng",F32,IF($B$2="Cơ sở",I32,L32)) -> 600 | P32: =IF($B$2="Thận trọng",G32,IF($B$2="Cơ sở",J32,M32)) -> 800 | Q32: Giả định ban đầu | R32: Đã xác nhận
A33: Tổ chức | B33: b2b_renewal | C33: Tỷ lệ gia hạn hợp đồng B2B | D33: % | E33: 0.8 | F33: 0.85 | G33: 0.88 | H33: 0.85 | I33: 0.88 | J33: 0.9 | K33: 0.88 | L33: 0.92 | M33: 0.94 | N33: =IF($B$2="Thận trọng",E33,IF($B$2="Cơ sở",H33,K33)) -> 0.85 | O33: =IF($B$2="Thận trọng",F33,IF($B$2="Cơ sở",I33,L33)) -> 0.88 | P33: =IF($B$2="Thận trọng",G33,IF($B$2="Cơ sở",J33,M33)) -> 0.9 | Q33: Giả định ban đầu | R33: Đã xác nhận
A34: C. GIÁ BÁN | C34: (r = 10%/năm, rf tháng = 10,47%)
A35: Giá bán | B35: premium_month | C35: Giá DIA+ Pro/ tháng | D35: VNĐ/tháng | E35: 29000 | F35: =E35*(1+10.47%) -> 32036.3 | G35: =E35*(1+10.47%) -> 32036.3 | H35: 39000 | I35: =H35*(1+10.47%) -> 43083.3 | J35: =H35*(1+10.47%)^2 -> 47594.122 | K35: 49000 | L35: =K35*(1+10.47%) -> 54130.3 | M35: =K35*(1+10.47%)^2 -> 59797.742 | N35: =IF($B$2="Thận trọng",E35,IF($B$2="Cơ sở",H35,K35)) -> 39000 | O35: =IF($B$2="Thận trọng",F35,IF($B$2="Cơ sở",I35,L35)) -> 43083.3 | P35: =IF($B$2="Thận trọng",G35,IF($B$2="Cơ sở",J35,M35)) -> 47594.122 | Q35: Giá khởi điểm phục vụ kiểm chứng willingness-to-pay. | R35: Đã kiểm chứng và báo giá
A36: Giá bán | B36: premium_year | C36: Giá DIA+ Pro / năm | D36: VNĐ/năm | E36: 299000 | F36: =E36*(1+10%) -> 328900 | G36: =E36*(1+10%)^2 -> 361790 | H36: 399000 | I36: =H36*(1+10%) -> 438900 | J36: =H36*(1+10%)^2 -> 482790 | K36: 499000 | L36: =K36*(1+10%) -> 548900 | M36: =K36*(1+10%)^2 -> 603790 | N36: =IF($B$2="Thận trọng",E36,IF($B$2="Cơ sở",H36,K36)) -> 399000 | O36: =IF($B$2="Thận trọng",F36,IF($B$2="Cơ sở",I36,L36)) -> 438900 | P36: =IF($B$2="Thận trọng",G36,IF($B$2="Cơ sở",J36,M36)) -> 482790 | Q36: Giả định giá khởi tạo – cần xác nhận | R36: Đã xác nhận
A37: Giá bán | B37: clinic_month | C37: Giá DIA+ Clinic / tháng | D37: VNĐ/tháng | E37: 799000 | F37: =E37*(1+10.47%)^12 -> 2639240.9 | G37: =E37*(1+10.47%)^24 -> 8717887.8 | H37: 899000 | I37: =H37*(1+10.47%) -> 993125.3 | J37: =H37*(1+10.47%)^2 -> 1097105.5 | K37: 999000 | L37: =K37*(1+10.47%) -> 1103595.3 | M37: =K37*(1+10.47%)^2 -> 1219141.7 | N37: =IF($B$2="Thận trọng",E37,IF($B$2="Cơ sở",H37,K37)) -> 899000 | O37: =IF($B$2="Thận trọng",F37,IF($B$2="Cơ sở",I37,L37)) -> 993125.3 | P37: =IF($B$2="Thận trọng",G37,IF($B$2="Cơ sở",J37,M37)) -> 1097105.5 | Q37: Giả định giá khởi tạo – cần xác nhận | R37: Đã xác nhận
A38: Giá bán | B38: clinic_month | C38: Giá DIA+ Clinic/năm | D38: VNĐ/tháng | E38: 7900000 | F38: =E38*(1+10%) -> 8690000 | G38: =E38*(1+10%)^2 -> 9559000 | H38: 8900000 | I38: =H38*(1+10%) -> 9790000 | J38: =H38*(1+10%)^2 -> 10769000 | K38: 9900000 | L38: =K38*(1+10%) -> 10890000 | M38: =K38*(1+10%)^2 -> 11979000 | N38: =IF($B$2="Thận trọng",E38,IF($B$2="Cơ sở",H38,K38)) -> 8900000 | O38: =IF($B$2="Thận trọng",F38,IF($B$2="Cơ sở",I38,L38)) -> 9790000 | P38: =IF($B$2="Thận trọng",G38,IF($B$2="Cơ sở",J38,M38)) -> 10769000 | Q38: Giả định giá khởi tạo – cần xác nhận | R38: Đã xác nhận
A39: Giá bán | B39: deploy_hospital_fee | C39: Phí triển khai / bệnh viện (Doanh thu) | D39: VNĐ/cơ sở | E39: 27000000 | F39: 27000000 | G39: 27000000 | H39: 30000000 | I39: 30000000 | J39: 30000000 | K39: 33000000 | L39: 33000000 | M39: 33000000 | N39: =IF($B$2="Thận trọng",E39,IF($B$2="Cơ sở",H39,K39)) -> 30000000 | O39: =IF($B$2="Thận trọng",F39,IF($B$2="Cơ sở",I39,L39)) -> 30000000 | P39: =IF($B$2="Thận trọng",G39,IF($B$2="Cơ sở",J39,M39)) -> 30000000 | Q39: Giả định giá khởi tạo – cần xác nhận | R39: Đã xác nhận
A40: Giá bán | B40: deploy_clinic_fee | C40: Phí triển khai / phòng khám (Doanh thu) | D40: VNĐ/cơ sở | E40: 9000000 | F40: 9000000 | G40: 9000000 | H40: 10000000 | I40: 10000000 | J40: 10000000 | K40: 11000000 | L40: 11000000 | M40: 11000000 | N40: =IF($B$2="Thận trọng",E40,IF($B$2="Cơ sở",H40,K40)) -> 10000000 | O40: =IF($B$2="Thận trọng",F40,IF($B$2="Cơ sở",I40,L40)) -> 10000000 | P40: =IF($B$2="Thận trọng",G40,IF($B$2="Cơ sở",J40,M40)) -> 10000000 | Q40: Giả định giá khởi tạo – cần xác nhận | R40: Đã xác nhận
...

Sheet DIA_Chi Phí
A1: DIA+ - KẾ HOẠCH CHI PHÍ
A4: A. CHI PHÍ ĐẦU TƯ BAN ĐẦU
A5: Khoản mục | B5: Số lượng | C5: Đơn giá | D5: Thành tiền | E5: Khấu hao / phân bổ? | F5: Thời gian phân bổ | G5: Ghi chú | H5: Nguồn / căn cứ | I5: Phân loại | K5: GHI CHÚ
A6: Nghiên cứu thị trường | B6: ='DIA_Giả Định'!$N$90 -> 1 | C6: ='DIA_Giả Định'!$N$91 -> 270000000 | D6: =B6*C6 -> 270000000 | E6: Không | F6: 0 | G6: Chi phí trước vận hành | H6: Giả định | I6: Chi phí trước vận hành | K6: 1. Năm 1 chưa thuê mặt bằng nên chưa định phí vào khoản này
A7: Hạ tầng công nghệ | B7: ='DIA_Giả Định'!$N$92 -> 1 | C7: ='DIA_Danh Mục Đầu Tư'!$D$25 -> 259850000 | D7: =B7*C7 -> 259850000 | E7: Có | F7: ='DIA_Giả Định'!$N$64 -> 1 | G7: Tài sản phần mềm | H7: Giả định | I7: Phần mềm
A8: Tích hợp AI | B8: ='DIA_Giả Định'!$N$96 -> 2 | C8: ='DIA_Giả Định'!$N$97 -> 8000000 | D8: =B8*C8 -> 16000000 | E8: Có | F8: ='DIA_Giả Định'!$N$64 -> 1 | G8: Tài sản phần mềm | H8: Giả định | I8: Phần mềm
A9: Bản quyền Microsoft 365 Family chính hãng (có AI Copilot) | B9: 1 | C9: ='DIA_Danh Mục Đầu Tư'!$D$14 -> 2600000 | D9: ='DIA_Danh Mục Đầu Tư'!$D$14 -> 2600000 | E9: Có | F9: ='DIA_Giả Định'!$N$64 -> 1 | G9: Tài sản phần mềm | H9: Giả định | I9: Phần mềm
A10: Bảo mật và lưu trữ thông tin | B10: 1 | C10: ='DIA_Danh Mục Đầu Tư'!$D$8 -> 96000000 | D10: ='DIA_Danh Mục Đầu Tư'!$E$8 -> 96000000 | F10: ='DIA_Giả Định'!$N$64 -> 1 | G10: Tài sản phần mềm | H10: Giả định | I10: Phần mềm
A11: Kiểm thử phần mềm | B11: ='DIA_Giả Định'!$N$98 -> 1 | C11: ='DIA_Giả Định'!$N$99 -> 40000000 | D11: =B11*C11 -> 40000000 | E11: Có | F11: ='DIA_Giả Định'!$N$64 -> 1 | G11: Đưa phần mềm vào trạng thái sẵn sàng | H11: Giả định | I11: Phần mềm
A12: Kiểm thử bảo mật | B12: ='DIA_Giả Định'!$N$100 -> 1 | C12: ='DIA_Giả Định'!$N$101 -> 40000000 | D12: =B12*C12 -> 40000000 | E12: Có | F12: ='DIA_Giả Định'!$N$64 -> 1 | G12: Đưa phần mềm vào trạng thái sẵn sàng | H12: Giả định | I12: Phần mềm
A13: Tư vấn pháp lý và đăng ký kinh doanh | B13: ='DIA_Giả Định'!$N$141 -> 6 | C13: ='DIA_Danh Mục Đầu Tư'!$D$18 -> 41000000 | D13: ='DIA_Danh Mục Đầu Tư'!$E$18 -> 41000000 | E13: Không | F13: 0 | G13: Chi phí trước vận hành | H13: Giả định | I13: Chi phí trước vận hành
A14: Thiết bị làm việc (laptop) | B14: ='DIA_Giả Định'!$N$114 -> 5 | C14: ='DIA_Giả Định'!$N$115 -> 24700000 | D14: =B14*C14 -> 123500000 | E14: Có | F14: ='DIA_Giả Định'!$N$65 -> 4 | G14: Thiết bị mạng, bảo mật, lưu trữ | H14: Giả định | I14: Tài sản hữu hình
A15: Điện thoại Iphone kiểm thử | B15: ='DIA_Giả Định'!$N$116 -> 1 | C15: ='DIA_Giả Định'!$N$117 -> 16300000 | D15: =B15*C15 -> 16300000 | E15: Có | F15: ='DIA_Giả Định'!$N$65 -> 4 | G15: Laptop, điện thoại, thiết bị demo | H15: Giả định | I15: Tài sản hữu hình
A16: Thí điểm tại bệnh viện | B16: ='DIA_Giả Định'!$N$118 -> 1 | C16: ='DIA_Giả Định'!$N$119 -> 80000000 | D16: =B16*C16 -> 80000000 | E16: Không | F16: 0 | G16: Chi phí thí điểm | H16: Giả định | I16: Chi phí trước vận hành
A17: Marketing ra mắt | B17: ='DIA_Giả Định'!$N$120 -> 1 | C17: ='DIA_Giả Định'!$N$121 -> 150000000 | D17: =B17*C17 -> 150000000 | E17: Không | F17: 0 | G17: Chi phí ra mắt | H17: Giả định | I17: Chi phí trước vận hành
A18: Đào tạo nhân sự | B18: ='DIA_Giả Định'!$N$122 -> 1 | C18: ='DIA_Giả Định'!$N$123 -> 20000000 | D18: =B18*C18 -> 20000000 | E18: Không | F18: 0 | G18: Chi phí trước vận hành | H18: Giả định | I18: Chi phí trước vận hành
A19: Vốn lưu động ban đầu | B19: ='DIA_Giả Định'!$N$124 -> 1 | C19: ='DIA_Giả Định'!$N$125 -> 300000000 | D19: =B19*C19 -> 300000000 | E19: Không | F19: 0 | G19: Dự trữ tiền mặt | H19: Giả định | I19: Vốn lưu động
A20: Dự phòng ban đầu - dự trù chi phí phát sinh | B20: ='DIA_Giả Định'!$N$126 -> 1 | C20: ='DIA_Giả Định'!$N$127 -> 300000000 | D20: =B20*C20 -> 300000000 | E20: Không | F20: 0 | G20: Dự phòng đầu tư | H20: Giả định | I20: Chi phí trước vận hành
A21: TỔNG ĐẦU TƯ BAN ĐẦU | D21: =SUM(D6:D20) -> 1755250000
A24: B. CHI PHÍ VẬN HÀNH CỐ ĐỊNH
A25: Khoản mục | B25: Tháng Năm 1 | C25: Năm 1 | D25: Tháng Năm 2 | E25: Năm 2 | F25: Tháng Năm 3 | G25: Năm 3 | H25: Nguồn / căn cứ | I25: Nhóm P&L
A26: Lương đội ngũ công nghệ | B26: ='DIA_Giả Định'!$N$75 -> 25000000 | C26: =B26*'DIA_Giả Định'!$N$5 -> 300000000 | D26: ='DIA_Giả Định'!$O$75 -> 30000000 | E26: =D26*'DIA_Giả Định'!$O$5 -> 360000000 | F26: ='DIA_Giả Định'!$P$75 -> 35000000 | G26: =F26*'DIA_Giả Định'!$P$5 -> 420000000 | H26: Giả định | I26: Nhân sự
A27: Lương sản phẩm và UI/UX | B27: ='DIA_Giả Định'!$N$76 -> 8000000 | C27: =B27*'DIA_Giả Định'!$N$5 -> 96000000 | D27: ='DIA_Giả Định'!$O$76 -> 9000000 | E27: =D27*'DIA_Giả Định'!$O$5 -> 108000000 | F27: ='DIA_Giả Định'!$P$76 -> 10000000 | G27: =F27*'DIA_Giả Định'!$P$5 -> 120000000 | H27: Giả định | I27: Nhân sự
A28: Lương chuyên môn y tế | B28: ='DIA_Giả Định'!$N$77 -> 6000000 | C28: =B28*'DIA_Giả Định'!$N$5 -> 72000000 | D28: ='DIA_Giả Định'!$O$77 -> 9000000 | E28: =D28*'DIA_Giả Định'!$O$5 -> 108000000 | F28: ='DIA_Giả Định'!$P$77 -> 12000000 | G28: =F28*'DIA_Giả Định'!$P$5 -> 144000000 | H28: Giả định | I28: Nhân sự
A29: Nhân sự kinh doanh B2B | B29: ='DIA_Giả Định'!$N$78 -> 8000000 | C29: =B29*'DIA_Giả Định'!$N$5 -> 96000000 | D29: ='DIA_Giả Định'!$O$78 -> 9500000 | E29: =D29*'DIA_Giả Định'!$O$5 -> 114000000 | F29: ='DIA_Giả Định'!$P$78 -> 12000000 | G29: =F29*'DIA_Giả Định'!$P$5 -> 144000000 | H29: Giả định | I29: Bán hàng & QLDN
A30: Marketing | B30: ='DIA_Giả Định'!$N$79 -> 15000000 | C30: =B30*'DIA_Giả Định'!$N$5 -> 180000000 | D30: ='DIA_Giả Định'!$O$79 -> 20000000 | E30: =D30*'DIA_Giả Định'!$O$5 -> 240000000 | F30: ='DIA_Giả Định'!$P$79 -> 25000000 | G30: =F30*'DIA_Giả Định'!$P$5 -> 300000000 | H30: Giả định | I30: Marketing
A31: Chăm sóc khách hàng | B31: ='DIA_Giả Định'!$N$80 -> 10000000 | C31: =B31*'DIA_Giả Định'!$N$5 -> 120000000 | D31: ='DIA_Giả Định'!$O$80 -> 12000000 | E31: =D31*'DIA_Giả Định'!$O$5 -> 144000000 | F31: ='DIA_Giả Định'!$P$80 -> 15000000 | G31: =F31*'DIA_Giả Định'!$P$5 -> 180000000 | H31: Giả định | I31: Nhân sự
A32: Kế toán và hành chính | B32: ='DIA_Giả Định'!$N$81 -> 7000000 | C32: =B32*'DIA_Giả Định'!$N$5 -> 84000000 | D32: ='DIA_Giả Định'!$O$81 -> 9000000 | E32: =D32*'DIA_Giả Định'!$O$5 -> 108000000 | F32: ='DIA_Giả Định'!$P$81 -> 12000000 | G32: =F32*'DIA_Giả Định'!$P$5 -> 144000000 | H32: Giả định | I32: Bán hàng & QLDN
A33: Thuê văn phòng văn phòng co - working | B33: - | C33: - | D33: ='DIA_Giả Định'!$O$82 -> 10000000 | E33: =D33*'DIA_Giả Định'!$N$5 -> 120000000 | F33: ='DIA_Giả Định'!$P$82 -> 12000000 | G33: =F33*'DIA_Giả Định'!$P$5 -> 144000000 | H33: Giả định | I33: Bán hàng & QLDN
A34: Phần mềm và công cụ làm việc | B34: ='DIA_Giả Định'!$N$83 -> 22812500 | C34: =B34*'DIA_Giả Định'!$N$5 -> 273750000 | D34: ='DIA_Giả Định'!$O$83 -> 22812500 | E34: =D34*'DIA_Giả Định'!$O$5 -> 273750000 | F34: ='DIA_Giả Định'!$P$83 -> 22812500 | G34: =F34*'DIA_Giả Định'!$P$5 -> 273750000 | H34: Giả định | I34: Công nghệ
A35: Kiểm tra bảo mật định kỳ | B35: ='DIA_Giả Định'!$N$84 -> 2000000 | C35: =B35*'DIA_Giả Định'!$N$5 -> 24000000 | D35: ='DIA_Giả Định'!$O$84 -> 4000000 | E35: =D35*'DIA_Giả Định'!$O$5 -> 48000000 | F35: ='DIA_Giả Định'!$P$84 -> 7000000 | G35: =F35*'DIA_Giả Định'!$P$5 -> 84000000 | H35: Giả định | I35: Công nghệ
A36: Pháp lý và tuân thủ dữ liệu | B36: =SUM(B37,B38) -> 10000000 | C36: =SUM(C37,C38) -> 120000000 | D36: =SUM(D37,D38) -> 14000000 | E36: =SUM(E37,E38) -> 168000000 | F36: =SUM(F37,F38) -> 18000000 | G36: =SUM(G37,G38) -> 216000000 | H36: Giả định | I36: Bán hàng & QLDN
A37: - Thuê tư vấn pháp lý / Kiểm toán tuân thủ định kỳ (Retainer Fee) | B37: 5000000 | C37: =B37*'DIA_Giả Định'!$N$5 -> 60000000 | D37: 7000000 | E37: =D37*'DIA_Giả Định'!$O$5 -> 84000000 | F37: 9000000 | G37: =F37*'DIA_Giả Định'!$P$5 -> 108000000 | H37: Giả định | I37: Bán hàng & QLDN
A38: - Nhân sự phụ trách bảo vệ dữ liệu (DPO - Data Protection Officer) | B38: 5000000 | C38: =B38*'DIA_Giả Định'!$N$5 -> 60000000 | D38: 7000000 | E38: =D38*'DIA_Giả Định'!$O$5 -> 84000000 | F38: 9000000 | G38: =F38*'DIA_Giả Định'!$P$5 -> 108000000 | H38: Giả định | I38: Bán hàng & QLDN
A39: Nghiên cứu và phát triển | B39: ='DIA_Giả Định'!$N$86 -> 4000000 | C39: =B39*'DIA_Giả Định'!$N$5 -> 48000000 | D39: ='DIA_Giả Định'!$O$86 -> 10000000 | E39: =D39*'DIA_Giả Định'!$O$5 -> 120000000 | F39: ='DIA_Giả Định'!$P$86 -> 18000000 | G39: =F39*'DIA_Giả Định'!$P$5 -> 216000000 | H39: Giả định | I39: Công nghệ
A40: Đi lại, demo, làm việc bệnh viện | B40: ='DIA_Giả Định'!$N$87 -> 3000000 | C40: =B40*'DIA_Giả Định'!$N$5 -> 36000000 | D40: ='DIA_Giả Định'!$O$87 -> 6000000 | E40: =D40*'DIA_Giả Định'!$O$5 -> 72000000 | F40: ='DIA_Giả Định'!$P$87 -> 12000000 | G40: =F40*'DIA_Giả Định'!$P$5 -> 144000000 | H40: Giả định | I40: Bán hàng & QLDN
A41: Dự phòng vận hành | B41: ='DIA_Giả Định'!$N$88 -> 6000000 | C41: =B41*'DIA_Giả Định'!$N$5 -> 72000000 | D41: ='DIA_Giả Định'!$O$88 -> 7000000 | E41: =D41*'DIA_Giả Định'!$O$5 -> 84000000 | F41: ='DIA_Giả Định'!$P$88 -> 8000000 | G41: =F41*'DIA_Giả Định'!$P$5 -> 96000000 | H41: Giả định | I41: Bán hàng & QLDN
A42: TỔNG ĐỊNH PHÍ | B42: =SUM(B26:B41) -> 136812500 | C42: =SUM(C26:C41) -> 1641750000 | D42: =SUM(D26:D41) -> 186312500 | E42: =SUM(E26:E41) -> 2235750000 | F42: =SUM(F26:F41) -> 236812500 | G42: =SUM(G26:G41) -> 2841750000
A45: C. CHI PHÍ BIẾN ĐỔI
A46: Khoản mục | B46: Cơ sở tính | C46: Đơn vị | D46: Năm 1 | E46: Năm 2 | F46: Năm 3 | G46: Nguồn | H46: Ghi chú | I46: Nhóm
...

Sheet DIA_Kịch Bản & Độ Nhạy
A1: DIA+ - PHÂN TÍCH KỊCH BẢN & ĐỘ NHẠY
A2: Ba kịch bản và bốn bảng độ nhạy được giữ nguyên; màu sắc và phân cấp tiêu đề được đồng bộ với mẫu YAMNUTRI.
A3: (giả định tỷ lệ giá vốn là 40%)
A4: SO SÁNH 3 KỊCH BẢN
A5: Chỉ tiêu | B5: Đơn vị | C5: Thận trọng | D5: Cơ sở | E5: Tích cực
A6: Tổng người dùng Năm 3 | B6: người | C6: =D23 -> 45000 | D6: =G23 -> 70000 | E6: =J23 -> 100000
A7: Tỷ lệ chuyển đổi Premium Năm 3 | B7: % | C7: ='DIA_Giả Định'!$G$8 -> 0.05 | D7: ='DIA_Giả Định'!$J$8 -> 0.06 | E7: ='DIA_Giả Định'!$M$8 -> 0.07
A8: Số cơ sở B2B Năm 3 | B8: cơ sở | C8: =D26 -> 21 | D8: =G26 -> 40 | E8: =J26 -> 55
A9: Doanh thu 3 năm | B9: VNĐ | C9: =SUM(B32:D32) -> 3.3068422e+09 | D9: =SUM(E32:G32) -> 5.5326636e+09 | E9: =SUM(H32:J32) -> 1.0923369e+10
A10: EBITDA 3 năm | B10: VNĐ | C10: =SUM(B35:D35) -> -4.5001087e+09 | D10: =SUM(E35:G35) -> -4.6376855e+09 | E10: =SUM(H35:J35) -> -4.4588506e+09
A11: Lợi nhuận sau thuế 3 năm | B11: VNĐ | C11: =SUM(B39:D39) -> -5.5989087e+09 | D11: =SUM(E39:G39) -> -5.8063355e+09 | E11: =SUM(H39:J39) -> -5.7268006e+09
A12: NPV | B12: VNĐ | C12: =B46 -> -3.3482872e+09 | D12: =E46 -> -3.7994462e+09 | E12: =H46 -> -4.4411218e+09
A13: IRR | B13: % | C13: =B47 -> 0 | D13: =E47 -> 0 | E13: =H47 -> 0
A14: Thời gian hoàn vốn | B14: năm | C14: =B48 -> >3 năm | D14: =E48 -> >3 năm | E14: =H48 -> >3 năm
A15: Nhu cầu vốn | B15: VNĐ | C15: =B49 -> 4.460552e+09 | D15: =E49 -> 4.9084434e+09 | E15: =H49 -> 5.4441655e+09
B20: KHỐI TÍNH - THẬN TRỌNG | E20: KHỐI TÍNH - CƠ SỞ | H20: KHỐI TÍNH - TÍCH CỰC
A21: Chỉ tiêu | B21: Năm 1 | C21: Năm 2 | D21: Năm 3 | E21: Năm 1 | F21: Năm 2 | G21: Năm 3 | H21: Năm 1 | I21: Năm 2 | J21: Năm 3
A22: Đầu tư ban đầu | B22: ='DIA_Giả Định'!$E$90*'DIA_Giả Định'!$E$91+'DIA_Giả Định'!$E$92*'DIA_Giả Định'!$E$93+'DIA_Giả Định'!$E$94*'DIA_Giả Định'!$E$95+'DIA_Giả Định'!$E$96*'DIA_Giả Định'!$E$97+'DIA_Giả Định'!$E$98*'DIA_Giả Định'!$E$99+'DIA_Giả Định'!$E$100*'DIA_Giả Định'!$E$101+'DIA_Giả Định'!$E$102*'DIA_Giả Định'!$E$103+'DIA_Giả Định'!$E$104*'DIA_Giả Định'!$E$105+'DIA_Giả Định'!$E$106*'DIA_Giả Định'!$E$107+'DIA_Giả Định'!$E$108*'DIA_Giả Định'!$E$109+'DIA_Giả Định'!$E$110*'DIA_Giả Định'!$E$111+'DIA_Giả Định'!$E$112*'DIA_Giả Định'!$E$113+'DIA_Giả Định'!$E$114*'DIA_Giả Định'!$E$115+'DIA_Giả Định'!$E$116*'DIA_Giả Định'!$E$117+'DIA_Giả Định'!$E$118*'DIA_Giả Định'!$E$119 -> 684600000 | C22: 0 | D22: 0 | E22: ='DIA_Giả Định'!$H$90*'DIA_Giả Định'!$H$91+'DIA_Giả Định'!$H$92*'DIA_Giả Định'!$H$93+'DIA_Giả Định'!$H$94*'DIA_Giả Định'!$H$95+'DIA_Giả Định'!$H$96*'DIA_Giả Định'!$H$97+'DIA_Giả Định'!$H$98*'DIA_Giả Định'!$H$99+'DIA_Giả Định'!$H$100*'DIA_Giả Định'!$H$101+'DIA_Giả Định'!$H$102*'DIA_Giả Định'!$H$103+'DIA_Giả Định'!$H$104*'DIA_Giả Định'!$H$105+'DIA_Giả Định'!$H$106*'DIA_Giả Định'!$H$107+'DIA_Giả Định'!$H$108*'DIA_Giả Định'!$H$109+'DIA_Giả Định'!$H$110*'DIA_Giả Định'!$H$111+'DIA_Giả Định'!$H$112*'DIA_Giả Định'!$H$113+'DIA_Giả Định'!$H$114*'DIA_Giả Định'!$H$115+'DIA_Giả Định'!$H$116*'DIA_Giả Định'!$H$117+'DIA_Giả Định'!$H$118*'DIA_Giả Định'!$H$119 -> 880400000 | F22: 0 | G22: 0 | H22: ='DIA_Giả Định'!$K$90*'DIA_Giả Định'!$K$91+'DIA_Giả Định'!$K$92*'DIA_Giả Định'!$K$93+'DIA_Giả Định'!$K$94*'DIA_Giả Định'!$K$95+'DIA_Giả Định'!$K$96*'DIA_Giả Định'!$K$97+'DIA_Giả Định'!$K$98*'DIA_Giả Định'!$K$99+'DIA_Giả Định'!$K$100*'DIA_Giả Định'!$K$101+'DIA_Giả Định'!$K$102*'DIA_Giả Định'!$K$103+'DIA_Giả Định'!$K$104*'DIA_Giả Định'!$K$105+'DIA_Giả Định'!$K$106*'DIA_Giả Định'!$K$107+'DIA_Giả Định'!$K$108*'DIA_Giả Định'!$K$109+'DIA_Giả Định'!$K$110*'DIA_Giả Định'!$K$111+'DIA_Giả Định'!$K$112*'DIA_Giả Định'!$K$113+'DIA_Giả Định'!$K$114*'DIA_Giả Định'!$K$115+'DIA_Giả Định'!$K$116*'DIA_Giả Định'!$K$117+'DIA_Giả Định'!$K$118*'DIA_Giả Định'!$K$119 -> 1086050000 | I22: 0 | J22: 0
A23: Tổng người dùng | B23: ='DIA_Giả Định'!$E$6 -> 20000 | C23: ='DIA_Giả Định'!$F$6 -> 30000 | D23: ='DIA_Giả Định'!$G$6 -> 45000 | E23: ='DIA_Giả Định'!$H$6 -> 40000 | F23: ='DIA_Giả Định'!$I$6 -> 50000 | G23: ='DIA_Giả Định'!$J$6 -> 70000 | H23: ='DIA_Giả Định'!$K$6 -> 50000 | I23: ='DIA_Giả Định'!$L$6 -> 70000 | J23: ='DIA_Giả Định'!$M$6 -> 100000
A24: MAU | B24: =('DIA_Giả Định'!$E$6*'DIA_Giả Định'!$E$7) -> 6000 | C24: =('DIA_Giả Định'!$F$6*'DIA_Giả Định'!$F$7) -> 12000 | D24: =('DIA_Giả Định'!$G$6*'DIA_Giả Định'!$G$7) -> 22500 | E24: =('DIA_Giả Định'!$H$6*'DIA_Giả Định'!$H$7) -> 14000 | F24: =('DIA_Giả Định'!$I$6*'DIA_Giả Định'!$I$7) -> 22500 | G24: =('DIA_Giả Định'!$J$6*'DIA_Giả Định'!$J$7) -> 38500 | H24: =('DIA_Giả Định'!$K$6*'DIA_Giả Định'!$K$7) -> 20000 | I24: =('DIA_Giả Định'!$L$6*'DIA_Giả Định'!$L$7) -> 35000 | J24: =('DIA_Giả Định'!$M$6*'DIA_Giả Định'!$M$7) -> 60000
A25: Người dùng Pro | B25: =('DIA_Giả Định'!$E$6*'DIA_Giả Định'!$E$8) -> 600 | C25: =('DIA_Giả Định'!$F$6*'DIA_Giả Định'!$F$8) -> 1200 | D25: =('DIA_Giả Định'!$G$6*'DIA_Giả Định'!$G$8) -> 2250 | E25: =('DIA_Giả Định'!$H$6*'DIA_Giả Định'!$H$8) -> 1600 | F25: =('DIA_Giả Định'!$I$6*'DIA_Giả Định'!$I$8) -> 2500 | G25: =('DIA_Giả Định'!$J$6*'DIA_Giả Định'!$J$8) -> 4200 | H25: =('DIA_Giả Định'!$K$6*'DIA_Giả Định'!$K$8) -> 2500 | I25: =('DIA_Giả Định'!$L$6*'DIA_Giả Định'!$L$8) -> 4200 | J25: =('DIA_Giả Định'!$M$6*'DIA_Giả Định'!$M$8) -> 7000
A26: Cơ sở B2B cuối năm | B26: ='DIA_Giả Định'!$E$25+'DIA_Giả Định'!$E$26 -> 4 | C26: ='DIA_Giả Định'!$F$25+'DIA_Giả Định'!$F$26 -> 13 | D26: ='DIA_Giả Định'!$G$25+'DIA_Giả Định'!$G$26 -> 21 | E26: ='DIA_Giả Định'!$H$25+'DIA_Giả Định'!$H$26 -> 7 | F26: ='DIA_Giả Định'!$I$25+'DIA_Giả Định'!$I$26 -> 20 | G26: ='DIA_Giả Định'!$J$25+'DIA_Giả Định'!$J$26 -> 40 | H26: ='DIA_Giả Định'!$K$25+'DIA_Giả Định'!$K$26 -> 11 | I26: ='DIA_Giả Định'!$L$25+'DIA_Giả Định'!$L$26 -> 30 | J26: ='DIA_Giả Định'!$M$25+'DIA_Giả Định'!$M$26 -> 55
A27: Cơ sở B2B bình quân | B27: =(('DIA_Giả Định'!$E$25*'DIA_Giả Định'!$E$30)*'DIA_Giả Định'!$E$37*'DIA_Giả Định'!$E$5+('DIA_Giả Định'!$E$26*'DIA_Giả Định'!$E$30)*'DIA_Giả Định'!$E$37*'DIA_Giả Định'!$E$5) -> 19176000 | C27: =(('DIA_Giả Định'!$F$25*'DIA_Giả Định'!$F$30)*'DIA_Giả Định'!$F$37*'DIA_Giả Định'!$F$5+('DIA_Giả Định'!$F$26*'DIA_Giả Định'!$F$30)*'DIA_Giả Định'!$F$37*'DIA_Giả Định'!$F$5) -> 2.0586079e+08 | D27: =(('DIA_Giả Định'!$G$25*'DIA_Giả Định'!$G$30)*'DIA_Giả Định'!$G$37*'DIA_Giả Định'!$G$5+('DIA_Giả Định'!$G$26*'DIA_Giả Định'!$G$30)*'DIA_Giả Định'!$G$37*'DIA_Giả Định'!$G$5) -> 1.0984539e+09 | E27: =(('DIA_Giả Định'!$H$25*'DIA_Giả Định'!$H$30)*'DIA_Giả Định'!$H$37*'DIA_Giả Định'!$H$5+('DIA_Giả Định'!$H$26*'DIA_Giả Định'!$H$30)*'DIA_Giả Định'!$H$37*'DIA_Giả Định'!$H$5) -> 37758000 | F27: =(('DIA_Giả Định'!$I$25*'DIA_Giả Định'!$I$30)*'DIA_Giả Định'!$I$37*'DIA_Giả Định'!$I$5+('DIA_Giả Định'!$I$26*'DIA_Giả Định'!$I$30)*'DIA_Giả Định'!$I$37*'DIA_Giả Định'!$I$5) -> 119175036 | G27: =(('DIA_Giả Định'!$J$25*'DIA_Giả Định'!$J$30)*'DIA_Giả Định'!$J$37*'DIA_Giả Định'!$J$5+('DIA_Giả Định'!$J$26*'DIA_Giả Định'!$J$30)*'DIA_Giả Định'!$J$37*'DIA_Giả Định'!$J$5) -> 2.6330532e+08 | H27: =(('DIA_Giả Định'!$K$25*'DIA_Giả Định'!$K$30)*'DIA_Giả Định'!$K$37*'DIA_Giả Định'!$K$5+('DIA_Giả Định'!$K$26*'DIA_Giả Định'!$K$30)*'DIA_Giả Định'!$K$37*'DIA_Giả Định'!$K$5) -> 65934000 | I27: =(('DIA_Giả Định'!$L$25*'DIA_Giả Định'!$L$30)*'DIA_Giả Định'!$L$37*'DIA_Giả Định'!$L$5+('DIA_Giả Định'!$L$26*'DIA_Giả Định'!$L$30)*'DIA_Giả Định'!$L$37*'DIA_Giả Định'!$L$5) -> 198647154 | J27: =(('DIA_Giả Định'!$M$25*'DIA_Giả Định'!$M$30)*'DIA_Giả Định'!$M$37*'DIA_Giả Định'!$M$5+('DIA_Giả Định'!$M$26*'DIA_Giả Định'!$M$30)*'DIA_Giả Định'!$M$37*'DIA_Giả Định'!$M$5) -> 4.0231677e+08
A28: Doanh thu B2C | B28: =(('DIA_Giả Định'!$E$6*'DIA_Giả Định'!$E$8)*'DIA_Giả Định'!$E$9*'DIA_Giả Định'!$E$35*'DIA_Giả Định'!$E$5+('DIA_Giả Định'!$E$6*'DIA_Giả Định'!$E$8)*'DIA_Giả Định'!$E$10*'DIA_Giả Định'!$E$36) -> 201450000 | C28: =(('DIA_Giả Định'!$F$6*'DIA_Giả Định'!$F$8)*'DIA_Giả Định'!$F$9*'DIA_Giả Định'!$F$35*'DIA_Giả Định'!$F$5+('DIA_Giả Định'!$F$6*'DIA_Giả Định'!$F$8)*'DIA_Giả Định'!$F$10*'DIA_Giả Định'!$F$36) -> 441329904 | D28: =(('DIA_Giả Định'!$G$6*'DIA_Giả Định'!$G$8)*'DIA_Giả Định'!$G$9*'DIA_Giả Định'!$G$35*'DIA_Giả Định'!$G$5+('DIA_Giả Định'!$G$6*'DIA_Giả Định'!$G$8)*'DIA_Giả Định'!$G$10*'DIA_Giả Định'!$G$36) -> 847146690 | E28: =(('DIA_Giả Định'!$H$6*'DIA_Giả Định'!$H$8)*'DIA_Giả Định'!$H$9*'DIA_Giả Định'!$H$35*'DIA_Giả Định'!$H$5+('DIA_Giả Định'!$H$6*'DIA_Giả Định'!$H$8)*'DIA_Giả Định'!$H$10*'DIA_Giả Định'!$H$36) -> 715680000 | F28: =(('DIA_Giả Định'!$I$6*'DIA_Giả Định'!$I$8)*'DIA_Giả Định'!$I$9*'DIA_Giả Định'!$I$35*'DIA_Giả Định'!$I$5+('DIA_Giả Định'!$I$6*'DIA_Giả Định'!$I$8)*'DIA_Giả Định'!$I$10*'DIA_Giả Định'!$I$36) -> 1224161850 | G28: =(('DIA_Giả Định'!$J$6*'DIA_Giả Định'!$J$8)*'DIA_Giả Định'!$J$9*'DIA_Giả Định'!$J$35*'DIA_Giả Định'!$J$5+('DIA_Giả Định'!$J$6*'DIA_Giả Định'!$J$8)*'DIA_Giả Định'!$J$10*'DIA_Giả Định'!$J$36) -> 2.2503334e+09 | H28: =(('DIA_Giả Định'!$K$6*'DIA_Giả Định'!$K$8)*'DIA_Giả Định'!$K$9*'DIA_Giả Định'!$K$35*'DIA_Giả Định'!$K$5+('DIA_Giả Định'!$K$6*'DIA_Giả Định'!$K$8)*'DIA_Giả Định'!$K$10*'DIA_Giả Định'!$K$36) -> 1392125000 | I28: =(('DIA_Giả Định'!$L$6*'DIA_Giả Định'!$L$8)*'DIA_Giả Định'!$L$9*'DIA_Giả Định'!$L$35*'DIA_Giả Định'!$L$5+('DIA_Giả Định'!$L$6*'DIA_Giả Định'!$L$8)*'DIA_Giả Định'!$L$10*'DIA_Giả Định'!$L$36) -> 2559052272 | J28: =(('DIA_Giả Định'!$M$6*'DIA_Giả Định'!$M$8)*'DIA_Giả Định'!$M$9*'DIA_Giả Định'!$M$35*'DIA_Giả Định'!$M$5+('DIA_Giả Định'!$M$6*'DIA_Giả Định'!$M$8)*'DIA_Giả Định'!$M$10*'DIA_Giả Định'!$M$36) -> 4.6645942e+09
A29: Doanh thu B2B | B29: =(('DIA_Giả Định'!$E$25*'DIA_Giả Định'!$E$30)*'DIA_Giả Định'!$E$37*'DIA_Giả Định'!$E$5+('DIA_Giả Định'!$E$26*'DIA_Giả Định'!$E$30)*'DIA_Giả Định'!$E$37*'DIA_Giả Định'!$E$5) -> 19176000 | C29: =(('DIA_Giả Định'!$F$25*'DIA_Giả Định'!$F$30)*'DIA_Giả Định'!$F$37*'DIA_Giả Định'!$F$5+('DIA_Giả Định'!$F$26*'DIA_Giả Định'!$F$30)*'DIA_Giả Định'!$F$37*'DIA_Giả Định'!$F$5) -> 2.0586079e+08 | D29: =(('DIA_Giả Định'!$G$25*'DIA_Giả Định'!$G$30)*'DIA_Giả Định'!$G$37*'DIA_Giả Định'!$G$5+('DIA_Giả Định'!$G$26*'DIA_Giả Định'!$G$30)*'DIA_Giả Định'!$G$37*'DIA_Giả Định'!$G$5) -> 1.0984539e+09 | E29: =(('DIA_Giả Định'!$H$25*'DIA_Giả Định'!$H$30)*'DIA_Giả Định'!$H$37*'DIA_Giả Định'!$H$5+('DIA_Giả Định'!$H$26*'DIA_Giả Định'!$H$30)*'DIA_Giả Định'!$H$37*'DIA_Giả Định'!$H$5) -> 37758000 | F29: =(('DIA_Giả Định'!$I$25*'DIA_Giả Định'!$I$30)*'DIA_Giả Định'!$I$37*'DIA_Giả Định'!$I$5+('DIA_Giả Định'!$I$26*'DIA_Giả Định'!$I$30)*'DIA_Giả Định'!$I$37*'DIA_Giả Định'!$I$5) -> 119175036 | G29: =(('DIA_Giả Định'!$J$25*'DIA_Giả Định'!$J$30)*'DIA_Giả Định'!$J$37*'DIA_Giả Định'!$J$5+('DIA_Giả Định'!$J$26*'DIA_Giả Định'!$J$30)*'DIA_Giả Định'!$J$37*'DIA_Giả Định'!$J$5) -> 2.6330532e+08 | H29: =(('DIA_Giả Định'!$K$25*'DIA_Giả Định'!$K$30)*'DIA_Giả Định'!$K$37*'DIA_Giả Định'!$K$5+('DIA_Giả Định'!$K$26*'DIA_Giả Định'!$K$30)*'DIA_Giả Định'!$K$37*'DIA_Giả Định'!$K$5) -> 65934000 | I29: =(('DIA_Giả Định'!$L$25*'DIA_Giả Định'!$L$30)*'DIA_Giả Định'!$L$37*'DIA_Giả Định'!$L$5+('DIA_Giả Định'!$L$26*'DIA_Giả Định'!$L$30)*'DIA_Giả Định'!$L$37*'DIA_Giả Định'!$L$5) -> 198647154 | J29: =(('DIA_Giả Định'!$M$25*'DIA_Giả Định'!$M$30)*'DIA_Giả Định'!$M$37*'DIA_Giả Định'!$M$5+('DIA_Giả Định'!$M$26*'DIA_Giả Định'!$M$30)*'DIA_Giả Định'!$M$37*'DIA_Giả Định'!$M$5) -> 4.0231677e+08
A30: Doanh thu triển khai | B30: ='DIA_Giả Định'!$E$27*'DIA_Giả Định'!$E$39+'DIA_Giả Định'!$E$28*'DIA_Giả Định'!$E$40 -> 54000000 | C30: =('DIA_Giả Định'!$F$27*'DIA_Giả Định'!$F$39+'DIA_Giả Định'!$F$28*'DIA_Giả Định'!$F$40) -> 117000000 | D30: =('DIA_Giả Định'!$G$27*'DIA_Giả Định'!$G$39+'DIA_Giả Định'!$G$28*'DIA_Giả Định'!$G$40) -> 189000000 | E30: ='DIA_Giả Định'!$H$27*'DIA_Giả Định'!$H$39+'DIA_Giả Định'!$H$28*'DIA_Giả Định'!$H$40 -> 110000000 | F30: =('DIA_Giả Định'!$I$27*'DIA_Giả Định'!$I$39+'DIA_Giả Định'!$I$28*'DIA_Giả Định'!$I$40) -> 190000000 | G30: =('DIA_Giả Định'!$J$27*'DIA_Giả Định'!$J$39+'DIA_Giả Định'!$J$28*'DIA_Giả Định'!$J$40) -> 350000000 | H30: ='DIA_Giả Định'!$K$27*'DIA_Giả Định'!$K$39+'DIA_Giả Định'!$K$28*'DIA_Giả Định'!$K$40 -> 187000000 | I30: =('DIA_Giả Định'!$L$27*'DIA_Giả Định'!$L$39+'DIA_Giả Định'!$L$28*'DIA_Giả Định'!$L$40) -> 319000000 | J30: =('DIA_Giả Định'!$M$27*'DIA_Giả Định'!$M$39+'DIA_Giả Định'!$M$28*'DIA_Giả Định'!$M$40) -> 539000000
A31: Doanh thu dịch vụ | B31: =('DIA_Giả Định'!$E$29*'DIA_Giả Định'!$E$41+'DIA_Giả Định'!$E$29*'DIA_Giả Định'!$E$43*'DIA_Giả Định'!$E$42) -> 15300000 | C31: =('DIA_Giả Định'!$F$29*'DIA_Giả Định'!$F$41+'DIA_Giả Định'!$F$29*'DIA_Giả Định'!$F$43*'DIA_Giả Định'!$F$42) -> 40500000 | D31: =('DIA_Giả Định'!$G$29*'DIA_Giả Định'!$G$41+'DIA_Giả Định'!$G$29*'DIA_Giả Định'!$G$43*'DIA_Giả Định'!$G$42) -> 77625000 | E31: =('DIA_Giả Định'!$H$29*'DIA_Giả Định'!$H$41+'DIA_Giả Định'!$H$29*'DIA_Giả Định'!$H$43*'DIA_Giả Định'!$H$42) -> 35000000 | F31: =('DIA_Giả Định'!$I$29*'DIA_Giả Định'!$I$41+'DIA_Giả Định'!$I$29*'DIA_Giả Định'!$I$43*'DIA_Giả Định'!$I$42) -> 74750000 | G31: =('DIA_Giả Định'!$J$29*'DIA_Giả Định'!$J$41+'DIA_Giả Định'!$J$29*'DIA_Giả Định'!$J$43*'DIA_Giả Định'!$J$42) -> 162500000 | H31: =('DIA_Giả Định'!$K$29*'DIA_Giả Định'!$K$41+'DIA_Giả Định'!$K$29*'DIA_Giả Định'!$K$43*'DIA_Giả Định'!$K$42) -> 73700000 | I31: =('DIA_Giả Định'!$L$29*'DIA_Giả Định'!$L$41+'DIA_Giả Định'!$L$29*'DIA_Giả Định'!$L$43*'DIA_Giả Định'!$L$42) -> 161500000 | J31: =('DIA_Giả Định'!$M$29*'DIA_Giả Định'!$M$41+'DIA_Giả Định'!$M$29*'DIA_Giả Định'!$M$43*'DIA_Giả Định'!$M$42) -> 360500000
A32: Tổng doanh thu | B32: =SUM(B28:B31) -> 289926000 | C32: =SUM(C28:C31) -> 8.0469069e+08 | D32: =SUM(D28:D31) -> 2.2122256e+09 | E32: =SUM(E28:E31) -> 898438000 | F32: =SUM(F28:F31) -> 1608086886 | G32: =SUM(G28:G31) -> 3.0261388e+09 | H32: =SUM(H28:H31) -> 1718759000 | I32: =SUM(I28:I31) -> 3238199426 | J32: =SUM(J28:J31) -> 5.966411e+09
A33: Chi phí biến đổi | B33: ='DIA_Giả Định'!$E$35*40%*'DIA_Giả Định'!$E$13 -> 69600000 | C33: ='DIA_Giả Định'!$F$35*40%*'DIA_Giả Định'!$F$13 -> 153774240 | D33: ='DIA_Giả Định'!$G$35*40%*'DIA_Giả Định'!$G$13 -> 288326700 | E33: ='DIA_Giả Định'!$H$35*40%*'DIA_Giả Định'!$H$13 -> 218400000 | F33: ='DIA_Giả Định'!$I$35*40%*'DIA_Giả Định'!$I$13 -> 387749700 | G33: ='DIA_Giả Định'!$J$35*40%*'DIA_Giả Định'!$J$13 -> 7.3294947e+08 | H33: ='DIA_Giả Định'!$K$35*40%*'DIA_Giả Định'!$K$13 -> 392000000 | I33: ='DIA_Giả Định'!$L$35*40%*'DIA_Giả Định'!$L$13 -> 757824200 | J33: ='DIA_Giả Định'!$M$35*40%*'DIA_Giả Định'!$M$13 -> 1.4351458e+09
A34: Chi phí cố định | B34: =SUM('DIA_Giả Định'!E75:E88)*12 -> 1767750000 | C34: =SUM('DIA_Giả Định'!F75:F88)*12 -> 2403750000 | D34: =SUM('DIA_Giả Định'!G75:G88)*12 -> 3123750000 | E34: =SUM('DIA_Giả Định'!H75:H88)*12 -> 2241750000 | F34: =SUM('DIA_Giả Định'!I75:I88)*12 -> 2979750000 | G34: =SUM('DIA_Giả Định'!J75:J88)*12 -> 3609750000 | H34: =SUM('DIA_Giả Định'!K75:K88)*12 -> 3117750000 | I34: =SUM('DIA_Giả Định'!L75:L88)*12 -> 4251750000 | J34: =SUM('DIA_Giả Định'!M75:M88)*12 -> 5427750000
A35: EBITDA | B35: =B32-B33-B34 -> -1547424000 | C35: =C32-C33-C34 -> -1.7528335e+09 | D35: =D32-D33-D34 -> -1.1998511e+09 | E35: =E32-E33-E34 -> -1561712000 | F35: =F32-F33-F34 -> -1759412814 | G35: =G32-G33-G34 -> -1.3165607e+09 | H35: =H32-H33-H34 -> -1790991000 | I35: =I32-I33-I34 -> -1771374774 | J35: =J32-J33-J34 -> -8.9648485e+08
A36: Khấu hao & phân bổ | B36: =((('DIA_Giả Định'!$E$92*'DIA_Giả Định'!$E$93)+('DIA_Giả Định'!$E$94*'DIA_Giả Định'!$E$95)+('DIA_Giả Định'!$E$104*'DIA_Giả Định'!$E$105)+('DIA_Giả Định'!$E$96*'DIA_Giả Định'!$E$97)+('DIA_Giả Định'!$E$98*'DIA_Giả Định'!$E$99)+('DIA_Giả Định'!$E$100*'DIA_Giả Định'!$E$101))/'DIA_Giả Định'!$E$64+(('DIA_Giả Định'!$E$114*'DIA_Giả Định'!$E$115)+('DIA_Giả Định'!$E$116*'DIA_Giả Định'!$E$117))/'DIA_Giả Định'!$E$65) -> 3.6626667e+08 | C36: =((('DIA_Giả Định'!$E$92*'DIA_Giả Định'!$E$93)+('DIA_Giả Định'!$E$94*'DIA_Giả Định'!$E$95)+('DIA_Giả Định'!$E$104*'DIA_Giả Định'!$E$105)+('DIA_Giả Định'!$E$96*'DIA_Giả Định'!$E$97)+('DIA_Giả Định'!$E$98*'DIA_Giả Định'!$E$99)+('DIA_Giả Định'!$E$100*'DIA_Giả Định'!$E$101))/'DIA_Giả Định'!$E$64+(('DIA_Giả Định'!$E$114*'DIA_Giả Định'!$E$115)+('DIA_Giả Định'!$E$116*'DIA_Giả Định'!$E$117))/'DIA_Giả Định'!$E$65) -> 3.6626667e+08 | D36: =((('DIA_Giả Định'!$E$92*'DIA_Giả Định'!$E$93)+('DIA_Giả Định'!$E$94*'DIA_Giả Định'!$E$95)+('DIA_Giả Định'!$E$104*'DIA_Giả Định'!$E$105)+('DIA_Giả Định'!$E$96*'DIA_Giả Định'!$E$97)+('DIA_Giả Định'!$E$98*'DIA_Giả Định'!$E$99)+('DIA_Giả Định'!$E$100*'DIA_Giả Định'!$E$101))/'DIA_Giả Định'!$E$64+(('DIA_Giả Định'!$E$114*'DIA_Giả Định'!$E$115)+('DIA_Giả Định'!$E$116*'DIA_Giả Định'!$E$117))/'DIA_Giả Định'!$E$65) -> 3.6626667e+08 | E36: =((('DIA_Giả Định'!$H$92*'DIA_Giả Định'!$H$93)+('DIA_Giả Định'!$H$94*'DIA_Giả Định'!$H$95)+('DIA_Giả Định'!$H$104*'DIA_Giả Định'!$H$105)+('DIA_Giả Định'!$H$96*'DIA_Giả Định'!$H$97)+('DIA_Giả Định'!$H$98*'DIA_Giả Định'!$H$99)+('DIA_Giả Định'!$H$100*'DIA_Giả Định'!$H$101))/'DIA_Giả Định'!$H$64+(('DIA_Giả Định'!$H$114*'DIA_Giả Định'!$H$115)+('DIA_Giả Định'!$H$116*'DIA_Giả Định'!$H$117))/'DIA_Giả Định'!$H$65) -> 389550000 | F36: =((('DIA_Giả Định'!$H$92*'DIA_Giả Định'!$H$93)+('DIA_Giả Định'!$H$94*'DIA_Giả Định'!$H$95)+('DIA_Giả Định'!$H$104*'DIA_Giả Định'!$H$105)+('DIA_Giả Định'!$H$96*'DIA_Giả Định'!$H$97)+('DIA_Giả Định'!$H$98*'DIA_Giả Định'!$H$99)+('DIA_Giả Định'!$H$100*'DIA_Giả Định'!$H$101))/'DIA_Giả Định'!$H$64+(('DIA_Giả Định'!$H$114*'DIA_Giả Định'!$H$115)+('DIA_Giả Định'!$H$116*'DIA_Giả Định'!$H$117))/'DIA_Giả Định'!$H$65) -> 389550000 | G36: =((('DIA_Giả Định'!$H$92*'DIA_Giả Định'!$H$93)+('DIA_Giả Định'!$H$94*'DIA_Giả Định'!$H$95)+('DIA_Giả Định'!$H$104*'DIA_Giả Định'!$H$105)+('DIA_Giả Định'!$H$96*'DIA_Giả Định'!$H$97)+('DIA_Giả Định'!$H$98*'DIA_Giả Định'!$H$99)+('DIA_Giả Định'!$H$100*'DIA_Giả Định'!$H$101))/'DIA_Giả Định'!$H$64+(('DIA_Giả Định'!$H$114*'DIA_Giả Định'!$H$115)+('DIA_Giả Định'!$H$116*'DIA_Giả Định'!$H$117))/'DIA_Giả Định'!$H$65) -> 389550000 | H36: =((('DIA_Giả Định'!$K$92*'DIA_Giả Định'!$K$93)+('DIA_Giả Định'!$K$94*'DIA_Giả Định'!$K$95)+('DIA_Giả Định'!$K$104*'DIA_Giả Định'!$K$105)+('DIA_Giả Định'!$K$96*'DIA_Giả Định'!$K$97)+('DIA_Giả Định'!$K$98*'DIA_Giả Định'!$K$99)+('DIA_Giả Định'!$K$100*'DIA_Giả Định'!$K$101))/'DIA_Giả Định'!$K$64+(('DIA_Giả Định'!$K$114*'DIA_Giả Định'!$K$115)+('DIA_Giả Định'!$K$116*'DIA_Giả Định'!$K$117))/'DIA_Giả Định'!$K$65) -> 422650000 | I36: =((('DIA_Giả Định'!$K$92*'DIA_Giả Định'!$K$93)+('DIA_Giả Định'!$K$94*'DIA_Giả Định'!$K$95)+('DIA_Giả Định'!$K$104*'DIA_Giả Định'!$K$105)+('DIA_Giả Định'!$K$96*'DIA_Giả Định'!$K$97)+('DIA_Giả Định'!$K$98*'DIA_Giả Định'!$K$99)+('DIA_Giả Định'!$K$100*'DIA_Giả Định'!$K$101))/'DIA_Giả Định'!$K$64+(('DIA_Giả Định'!$K$114*'DIA_Giả Định'!$K$115)+('DIA_Giả Định'!$K$116*'DIA_Giả Định'!$K$117))/'DIA_Giả Định'!$K$65) -> 422650000 | J36: =((('DIA_Giả Định'!$K$92*'DIA_Giả Định'!$K$93)+('DIA_Giả Định'!$K$94*'DIA_Giả Định'!$K$95)+('DIA_Giả Định'!$K$104*'DIA_Giả Định'!$K$105)+('DIA_Giả Định'!$K$96*'DIA_Giả Định'!$K$97)+('DIA_Giả Định'!$K$98*'DIA_Giả Định'!$K$99)+('DIA_Giả Định'!$K$100*'DIA_Giả Định'!$K$101))/'DIA_Giả Định'!$K$64+(('DIA_Giả Định'!$K$114*'DIA_Giả Định'!$K$115)+('DIA_Giả Định'!$K$116*'DIA_Giả Định'!$K$117))/'DIA_Giả Định'!$K$65) -> 422650000
A37: EBIT | B37: =B35-B36 -> -1.9136907e+09 | C37: =C35-C36 -> -2.1191002e+09 | D37: =D35-D36 -> -1.5661178e+09 | E37: =E35-E36 -> -1951262000 | F37: =F35-F36 -> -2148962814 | G37: =G35-G36 -> -1.7061107e+09 | H37: =H35-H36 -> -2213641000 | I37: =I35-I36 -> -2194024774 | J37: =J35-J36 -> -1.3191348e+09
A38: Thuế | B38: =MAX(0,B37*'DIA_Giả Định'!$E$59) -> 0 | C38: =MAX(0,C37*'DIA_Giả Định'!$F$59) -> 0 | D38: =MAX(0,D37*'DIA_Giả Định'!$G$59) -> 0 | E38: =MAX(0,E37*'DIA_Giả Định'!$H$59) -> 0 | F38: =MAX(0,F37*'DIA_Giả Định'!$I$59) -> 0 | G38: =MAX(0,G37*'DIA_Giả Định'!$J$59) -> 0 | H38: =MAX(0,H37*'DIA_Giả Định'!$K$59) -> 0 | I38: =MAX(0,I37*'DIA_Giả Định'!$L$59) -> 0 | J38: =MAX(0,J37*'DIA_Giả Định'!$M$59) -> 0
A39: Lợi nhuận sau thuế | B39: =B37-B38 -> -1.9136907e+09 | C39: =C37-C38 -> -2.1191002e+09 | D39: =D37-D38 -> -1.5661178e+09 | E39: =E37-E38 -> -1951262000 | F39: =F37-F38 -> -2148962814 | G39: =G37-G38 -> -1.7061107e+09 | H39: =H37-H38 -> -2213641000 | I39: =I37-I38 -> -2194024774 | J39: =J37-J38 -> -1.3191348e+09
A40: Chi đầu tư bổ sung | B40: =-'DIA_Giả Định'!$E$73 -> 0 | C40: =-'DIA_Giả Định'!$F$73 -> -50000000 | D40: =-'DIA_Giả Định'!$G$73 -> -80000000 | E40: =-'DIA_Giả Định'!$H$73 -> 0 | F40: =-'DIA_Giả Định'!$I$73 -> -100000000 | G40: =-'DIA_Giả Định'!$J$73 -> -150000000 | H40: =-'DIA_Giả Định'!$K$73 -> 0 | I40: =-'DIA_Giả Định'!$L$73 -> -200000000 | J40: =-'DIA_Giả Định'!$M$73 -> -300000000
A41: Thay đổi vốn lưu động | B41: =-MAX(0,(B34/'DIA_Giả Định'!$E$5*'DIA_Giả Định'!$E$67)-('DIA_Giả Định'!$E$124*'DIA_Giả Định'!$E$125)) -> -39625000 | C41: =-MAX(0,(C34/'DIA_Giả Định'!$F$5*'DIA_Giả Định'!$F$67)-(B34/'DIA_Giả Định'!$E$5*'DIA_Giả Định'!$E$67)) -> -106000000 | D41: =-MAX(0,(D34/'DIA_Giả Định'!$G$5*'DIA_Giả Định'!$G$67)-(C34/'DIA_Giả Định'!$F$5*'DIA_Giả Định'!$F$67)) -> -120000000 | E41: =-MAX(0,(E34/'DIA_Giả Định'!$H$5*'DIA_Giả Định'!$H$67)-('DIA_Giả Định'!$H$124*'DIA_Giả Định'!$H$125)) -> -73625000 | F41: =-MAX(0,(F34/'DIA_Giả Định'!$I$5*'DIA_Giả Định'!$I$67)-(E34/'DIA_Giả Định'!$H$5*'DIA_Giả Định'!$H$67)) -> -123000000 | G41: =-MAX(0,(G34/'DIA_Giả Định'!$J$5*'DIA_Giả Định'!$J$67)-(F34/'DIA_Giả Định'!$I$5*'DIA_Giả Định'!$I$67)) -> -105000000 | H41: =-MAX(0,(H34/'DIA_Giả Định'!$K$5*'DIA_Giả Định'!$K$67)-('DIA_Giả Định'!$K$124*'DIA_Giả Định'!$K$125)) -> -159625000 | I41: =-MAX(0,(I34/'DIA_Giả Định'!$L$5*'DIA_Giả Định'!$L$67)-(H34/'DIA_Giả Định'!$K$5*'DIA_Giả Định'!$K$67)) -> -189000000 | J41: =-MAX(0,(J34/'DIA_Giả Định'!$M$5*'DIA_Giả Định'!$M$67)-(I34/'DIA_Giả Định'!$L$5*'DIA_Giả Định'!$L$67)) -> -196000000
A42: FCF | B42: =B37*(1-'DIA_Giả Định'!$E$59)+B36+B40+B41 -> -1.2043109e+09 | C42: =C37*(1-'DIA_Giả Định'!$F$59)+C36+C40+C41 -> -1.4850135e+09 | D42: =D37*(1-'DIA_Giả Định'!$G$59)+D36+D40+D41 -> -1.0866276e+09 | E42: =E37*(1-'DIA_Giả Định'!$H$59)+E36+E40+E41 -> -1245084600 | F42: =F37*(1-'DIA_Giả Định'!$I$59)+F36+F40+F41 -> -1.5526203e+09 | G42: =G37*(1-'DIA_Giả Định'!$J$59)+G36+G40+G41 -> -1.2303386e+09 | H42: =H37*(1-'DIA_Giả Định'!$K$59)+H36+H40+H41 -> -1507887800 | I42: =I37*(1-'DIA_Giả Định'!$L$59)+I36+I40+I41 -> -1.7215698e+09 | J42: =J37*(1-'DIA_Giả Định'!$M$59)+J36+J40+J41 -> -1.1286579e+09
A43: FCF chiết khấu | B43: =B42/POWER(1+'DIA_Giả Định'!$E$60,1) -> -1.0035924e+09 | C43: =C42/POWER(1+'DIA_Giả Định'!$E$60,2) -> -1.0312594e+09 | D43: =D42/POWER(1+'DIA_Giả Định'!$E$60,3) -> -6.2883541e+08 | E43: =E42/POWER(1+'DIA_Giả Định'!$H$60,1) -> -1.0551564e+09 | F43: =F42/POWER(1+'DIA_Giả Định'!$H$60,2) -> -1.1150677e+09 | G43: =G42/POWER(1+'DIA_Giả Định'!$H$60,3) -> -7.4882204e+08 | H43: =H42/POWER(1+'DIA_Giả Định'!$K$60,1) -> -1.3112068e+09 | I43: =I42/POWER(1+'DIA_Giả Định'!$K$60,2) -> -1.3017541e+09 | J43: =J42/POWER(1+'DIA_Giả Định'!$K$60,3) -> -7.4211088e+08
A44: FCF lũy kế | B44: =-B22+B42 -> -1.8889109e+09 | C44: =B44+C42 -> -3.3739244e+09 | D44: =C44+D42 -> -4.460552e+09 | E44: =-E22+E42 -> -2125484600 | F44: =E44+F42 -> -3.6781049e+09 | G44: =F44+G42 -> -4.9084434e+09 | H44: =-H22+H42 -> -2593937800 | I44: =H44+I42 -> -4.3155076e+09 | J44: =I44+J42 -> -5.4441655e+09
...

Sheet DIA_Hiệu Quả TC
A1: DIA+ - HIỆU QUẢ TÀI CHÍNH 3 NĂM
A3: 1. THÔNG SỐ
A4: Chỉ tiêu | B4: Giá trị | C4: Ghi chú
A5: Tổng đầu tư ban đầu | B5: ='DIA_Chi Phí'!$D$21 -> 1755250000 | C5: Liên kết DIA_Chi Phí / DIA_Giả Định
A6: Tài sản hữu hình | B6: =SUMIF('DIA_Chi Phí'!$I$6:$I$20,"Tài sản hữu hình",'DIA_Chi Phí'!$D$6:$D$20) -> 139800000 | C6: Liên kết DIA_Chi Phí / DIA_Giả Định
A7: Chi phí phát triển phần mềm được phân bổ | B7: =SUMIF('DIA_Chi Phí'!$I$6:$I$20,"Phần mềm",'DIA_Chi Phí'!$D$6:$D$20) -> 454450000 | C7: Liên kết DIA_Chi Phí / DIA_Giả Định
A8: Vốn lưu động | B8: ='DIA_Chi Phí'!$D$19 -> 300000000 | C8: Liên kết DIA_Chi Phí / DIA_Giả Định
A9: Vốn vay | B9: =B5*'DIA_Giả Định'!$N$61 -> 0 | C9: Liên kết DIA_Chi Phí / DIA_Giả Định
A10: Vốn chủ sở hữu | B10: =B5-B9 -> 1755250000 | C10: Liên kết DIA_Chi Phí / DIA_Giả Định
A11: Lãi suất | B11: ='DIA_Giả Định'!$N$62 -> 0.1 | C11: Liên kết DIA_Chi Phí / DIA_Giả Định
A12: Suất chiết khấu | B12: ='DIA_Giả Định'!$N$60 -> 0.18 | C12: Liên kết DIA_Chi Phí / DIA_Giả Định
A13: Thuế TNDN | B13: ='DIA_Giả Định'!$N$59 -> 0.2 | C13: Liên kết DIA_Chi Phí / DIA_Giả Định
A14: Thời gian phân bổ phần mềm | B14: ='DIA_Giả Định'!$N$64 -> 1 | C14: Liên kết DIA_Chi Phí / DIA_Giả Định
A15: Vòng đời dự án | B15: ='DIA_Giả Định'!$N$66 -> 3 | C15: Liên kết DIA_Chi Phí / DIA_Giả Định
A17: 2. KẾ HOẠCH TÀI CHÍNH
A18: 2.1. Kế hoạch vay và trả nợ hàng năm
A19: Chỉ tiêu | B19: Năm 1 | C19: Năm 2 | D19: Năm 3
A20: Nợ đầu kỳ | B20: =IF('DIA_Giả Định'!$N$61=0,0,B9) -> 0 | C20: =B24 -> 0 | D20: =C24 -> 0
A21: Lãi phát sinh | B21: =IF('DIA_Giả Định'!$N$61=0,0,B20*'DIA_Giả Định'!$N$62) -> 0 | C21: =IF('DIA_Giả Định'!$N$61=0,0,C20*'DIA_Giả Định'!$O$62) -> 0 | D21: =IF('DIA_Giả Định'!$N$61=0,0,D20*'DIA_Giả Định'!$P$62) -> 0
A22: Trả lãi | B22: =B21 -> 0 | C22: =C21 -> 0 | D22: =D21 -> 0
A23: Trả gốc | B23: =IF('DIA_Giả Định'!$N$61=0,0,MIN(B20,B9/'DIA_Giả Định'!$N$71)) -> 0 | C23: =IF('DIA_Giả Định'!$N$61=0,0,MIN(C20,B9/'DIA_Giả Định'!$N$71)) -> 0 | D23: =IF('DIA_Giả Định'!$N$61=0,0,MIN(D20,B9/'DIA_Giả Định'!$N$71)) -> 0
A24: Nợ cuối kỳ | B24: =MAX(0,B20-B23) -> 0 | C24: =MAX(0,C20-C23) -> 0 | D24: =MAX(0,D20-D23) -> 0
A27: 2.2. Kế hoạch thu nhập hàng năm
A28: Chỉ tiêu | B28: Năm 1 | C28: Năm 2 | D28: Năm 3
A29: Tổng doanh thu | B29: ='DIA_Giá và Doanh Thu'!$F$20 -> 994450000 | C29: ='DIA_Giá và Doanh Thu'!$G$20 -> 2019266886 | D29: ='DIA_Giá và Doanh Thu'!$H$20 -> 4.0611751e+09
A30: Doanh thu B2C | B30: ='DIA_Giá và Doanh Thu'!$F$15 -> 715680000 | C30: ='DIA_Giá và Doanh Thu'!$G$15 -> 1224161850 | D30: ='DIA_Giá và Doanh Thu'!$H$15 -> 2.2503334e+09
A31: Doanh thu B2B | B31: ='DIA_Giá và Doanh Thu'!$F$16 -> 133770000 | C31: ='DIA_Giá và Doanh Thu'!$G$16 -> 530355036 | D31: ='DIA_Giá và Doanh Thu'!$H$16 -> 1.2983417e+09
A32: Doanh thu triển khai & dịch vụ | B32: ='DIA_Giá và Doanh Thu'!$F$18+'DIA_Giá và Doanh Thu'!$F$19 -> 85000000 | C32: ='DIA_Giá và Doanh Thu'!$G$18+'DIA_Giá và Doanh Thu'!$G$19 -> 174750000 | D32: ='DIA_Giá và Doanh Thu'!$H$18+'DIA_Giá và Doanh Thu'!$H$19 -> 362500000
A33: Chi phí biến đổi | B33: ='DIA_Chi Phí'!$D$58 -> 554347250 | C33: ='DIA_Chi Phí'!$E$58 -> 1.0256883e+09 | D33: ='DIA_Chi Phí'!$F$58 -> 1.977498e+09
A34: Lợi nhuận gộp | B34: =B29-B33 -> 440102750 | C34: =C29-C33 -> 9.9357858e+08 | D34: =D29-D33 -> 2.083677e+09
A35: Gross Margin | B35: =IFERROR(B34/B29,0) -> 0.44255895 | C35: =IFERROR(C34/C29,0) -> 0.49204916 | D35: =IFERROR(D34/D29,0) -> 0.51307245
A36: Chi phí nhân sự | B36: =SUMIF('DIA_Chi Phí'!$I$26:$I$41,"Nhân sự",'DIA_Chi Phí'!$C$26:$C$41) -> 588000000 | C36: =SUMIF('DIA_Chi Phí'!$I$26:$I$41,"Nhân sự",'DIA_Chi Phí'!$E$26:$E$41) -> 720000000 | D36: =SUMIF('DIA_Chi Phí'!$I$26:$I$41,"Nhân sự",'DIA_Chi Phí'!$G$26:$G$41) -> 864000000
